Workbook
Name \a: [1]期末提出!#REF!
Name ______Ro2: #REF!
Name ______Vo2: #REF!
Name ______Vo3: #REF!
Name _____Ro2: #REF!
Name _____Vo2: #REF!
Name _____Vo3: #REF!
Name ____Ro2: #REF!
Name ____Vo2: #REF!
Name ____Vo3: #REF!
Name ___DEL1: #REF!
Name ___DEL2: #REF!
Name ___DEL3: #REF!
Name ___DS10: [2]list!$M$23:$M$39
Name ___PRT1: #REF!
Name ___PRT2: #REF!
Name ___PRT3: #REF!
Name ___Ro2: #REF!
Name ___Vo2: #REF!
Name ___Vo3: #REF!
Name __DEL1: #REF!
Name __DEL2: #REF!
Name __DEL3: #REF!
Name __DS10: [2]list!$M$23:$M$39
Name __PRT1: #REF!
Name __PRT2: #REF!
Name __PRT3: #REF!
Name __Ro2: #REF!
Name __Vo2: #REF!
Name __Vo3: #REF!
Name _DAT1: #REF!
Name _DAT10: #REF!
Name _DAT11: #REF!
Name _DAT12: #REF!
Name _DAT13: #REF!
Name _DAT14: #REF!
Name _DAT15: #REF!
Name _DAT16: #REF!
Name _DAT17: #REF!
Name _DAT18: #REF!
Name _DAT19: #REF!
Name _DAT2: #REF!
Name _DAT20: #REF!
Name _DAT21: #REF!
Name _DAT22: #REF!
Name _DAT23: #REF!
Name _DAT24: #REF!
Name _DAT25: #REF!
Name _DAT26: #REF!
Name _DAT27: #REF!
Name _DAT28: #REF!
Name _DAT29: #REF!
Name _DAT3: #REF!
Name _DAT4: #REF!
Name _DAT5: #REF!
Name _DAT6: #REF!
Name _DAT7: #REF!
Name _DAT8: #REF!
Name _DAT9: #REF!
Name _DEL1: #REF!

Sheet 進度確認表(New)
N1: 対報告書 未完成件数 | P1: =COUNTIF(AG7:AG2090,"CLOSE")-COUNTIF(AH7:AH1090,"CLOSE")&" 件" -> -51 件 | R1: 対報告書 達成目標 | T1: =ROUNDDOWN(COUNTIF(AH7:AH624,"CLOSE")/COUNTIF(AH7:AH624,"CLOSE"),1) -> 1 | V1: 點檢日 ：未實施 實施內容 ：未實施 預定日 ：7月中旬（Wizus→AN100素地替中） 對策内容 ： ・鍊條及軸承上給油。 ・油管硬化疑慮，汰換新管預定。 實施完成日：○月○日 定期管理 ：工事日給油；點檢：製造:1回/半年，設技: 1回/年。 | Z1: YF 未完成 | AA1: CF 未完成 | AB1: EF 未完成 | AC1: JF 未完成 | AD1: KF 未完成 | AE1: TAS 未完成 | AF1: OFF切 未完成
A2: ADT設備異常、改善、横展開進度確認表 | K2: 【設備ロス削減チーム Link】 | Z2: =COUNTIF(Z7:Z1090,"未") -> 3 | AA2: =COUNTIF(AA7:AA1090,"未") -> 4 | AB2: =COUNTIF(AB7:AB1090,"未") -> 3 | AC2: =COUNTIF(AC7:AC1090,"未") -> 3 | AD2: =COUNTIF(AD7:AD1090,"未") -> 2 | AE2: =COUNTIF(AE7:AE1090,"未") -> 0 | AF2: =COUNTIF(AF7:AF1090,"未") -> 0
Z3: ='横展開率 (舊)'!D4 -> #DIV/0! | AA3: ='横展開率 (舊)'!L4 -> #DIV/0! | AB3: ='横展開率 (舊)'!T4 -> #DIV/0! | AC3: ='横展開率 (舊)'!D26 -> #DIV/0! | AD3: ='横展開率 (舊)'!L26 -> #DIV/0! | AE3: ='横展開率 (舊)'!D50 -> #DIV/0! | AF3: 1
H5: 報告対象 | I5: 中文 報告 | J5: 關聯 資料 | N5: 初回/ 再發 | O5: 停止 時間 (MIN) | P5: LOSS (m2) | Q5: 機會損失 (m2) | R5: 横展開必要LINE | Z5: 各LINE横展開進度 | AG5: 最終結果
A6: 編號№ | B6: 日付 | C6: 場所 （1） | D6: 場所 （2） | E6: 擔當者 | F6: 種別 | G6: 設備名 | H6: 報告対象 | I6: 中文 報告 | J6: 關聯 資料 | K6: 内容 | L6: 原因調査 | M6: 對策内容 | N6: 初回/ 再發 | O6: 停止 時間 (MIN) | P6: LOSS (m2) | Q6: 機會損失 (m2) | R6: YF | S6: CF | T6: EF | U6: JF | V6: KF | W6: TAS | X6: OFF切 | Y6: 横展開方針 | Z6: YF | AA6: CF | AB6: EF | AC6: JF | AD6: KF | AE6: TAS | AF6: OFF切 | AG6: 方針 CLOSE | AH6: 對策 CLOSE | AI6: 完成度 | AJ6: 備考
A7: 1401 | B7: 41798 | C7: ADT | D7: JF | E7: 三路 | F7: 檢查系 | G7: TOM3 | H7: 他拠点報告 | I7: ー | K7: ・歪CAMERA#4 故障 | L7: ・第4TAP發生鬍鬚状的雜訊。 ※推測是歪CAMERA内部的接点不良。 | M7: ・CAMERA更換 ・在歪CAMERA的異常発現用處作成#970GATE ・作成和教育光量異常警報発生時，異常画像発現時的作業流程。 | N7: 初回 | O7: 10 | P7: 259 | R7: 要 | S7: 要 | T7: 要 | U7: - | V7: 要 | W7: - | X7: - | Y7: ・追加#970GATE ・教育光量異常警報発生時，異常画像発現時的作業流程。 | Z7: 完了 | AA7: 完了 | AB7: 完了 | AC7: - | AD7: 完了 | AE7: - | AF7: - | AG7: =IF(Y7="","","CLOSE") -> CLOSE | AH7: =IF(E7="","",IF(COUNTIF(Z7:AE7,"未")=0,"CLOSE","")) -> CLOSE | AI7: =COUNTIF(Z7:AF7,"完了")/COUNTIF(R7:X7,"要") -> 1
A8: =A7+1 -> 1402 | B8: 41812 | C8: ADT | D8: JF | E8: 蔡明建 三路 | F8: 檢查系 | G8: WI | H8: 他拠点報告 | I8: O:\00 製造一部共通\横展開確認\設備異常報告\異常報告書(日文) | J8: O:\00 製造一部共通\横展開確認\設備異常報告\異常報告書(日文)\201406\WI台車抜き出しマニュアル | K8: ・WI CAMERA#11波形異常 | L8: ・推測有落下物掉在CAMERA或光原條紋片上。 ※造成波形異常,影響了平坦度值。 | M8: ・拖出WI光源CAMERA基座,用AIR清除灰塵異物 ・制定連續平坦度惡化時確認流程並教育訓練 ・制定WI光源CAMERA基座拖出的手順並教育訓練. | N8: 初回 | O8: 0 | P8: 0 | R8: 要 | S8: 要 | T8: 要 | U8: - | V8: 要 | W8: - | X8: - | Y8: ・制定連續平坦度惡化時確認流程並教育訓練。 ・制定WI光源CAMERA基座拖出的手順並教育訓練. | Z8: 完了 | AA8: 完了 | AB8: 完了 | AC8: - | AD8: 完了 | AE8: - | AF8: - | AG8: =IF(Y8="","","CLOSE") -> CLOSE | AH8: =IF(E8="","",IF(COUNTIF(Z8:AE8,"未")=0,"CLOSE","")) -> CLOSE | AI8: =COUNTIF(Z8:AF8,"完了")/COUNTIF(R8:X8,"要") -> 1
A9: =A8+1 -> 1403 | B9: 41798 | C9: AFK | D9: LF | E9: 鄭吉勝 | F9: 電氣系 | G9: 帯電Bar | H9: ADT以外 | I9: ..\..\異常報告書(中文)\201406\●LF帯電装置過電流Trip異常-(C_E_J_K_Y_Z)帶電Bar確認.xls | K9: ・LF 帯電装置過電流Trip異常 | L9: ・現場濕度高（65%）的状態下、電荷從帶電Bar樹脂部之裂縫、或是樹脂部的髒污處流竄到支架上，導致過電流並跳脫。 ・由於使用高電壓、絶縁部多少都會因為電氣流動的因素產生裂縫。 | M9: ・工事日時都針對帶電Bar樹脂部實施掃除。 ・裂縫實施Silicon Caulking。 ・帶電Bar的下方設置傳導體（SUS pipe） | N9: 初回 | O9: 95 | P9: 2820 | R9: 要 | S9: 要 | T9: 要 | U9: 要 | V9: 要 | W9: 要 | X9: - | Y9: ・帶電Bar數量確認 ・帶電Bar本體點檢 ・掃除/點檢頻度確認 | Z9: 完了 | AA9: 完了 | AB9: 完了 | AC9: 完了 | AD9: 完了 | AE9: 完了 | AF9: - | AG9: =IF(Y9="","","CLOSE") -> CLOSE | AH9: =IF(E9="","",IF(COUNTIF(Z9:AE9,"未")=0,"CLOSE","")) -> CLOSE | AI9: =COUNTIF(Z9:AF9,"完了")/COUNTIF(R9:X9,"要") -> 1
A10: =A9+1 -> 1404 | B10: 41820 | C10: 全拠点 | D10: 全ライン | E10: 三路 | F10: 系統系 | G10: PAM | H10: ADT以外 | I10: O:\00 製造一部共通\横展開確認\設備異常報告\異常報告書(日文)\201406\20140630 PAM改修.xls | K10: ・PL№無法連結 | L10: ・相同的生産指示書號碼進行2次以上J/C時，發生與PAM内部所持有的號碼不一致，造成PLNo無法連結的現象。 | M10: ・修正版的發行 | N10: 初回 | O10: 0 | P10: 0 | R10: 要 | S10: 要 | T10: 要 | U10: 要 | V10: 要 | W10: - | X10: - | Y10: ・修正版的發行 | Z10: 完了 | AA10: 完了 | AB10: 完了 | AC10: 完了 | AD10: 完了 | AE10: - | AF10: - | AG10: =IF(Y10="","","CLOSE") -> CLOSE | AH10: =IF(E10="","",IF(COUNTIF(Z10:AE10,"未")=0,"CLOSE","")) -> CLOSE | AI10: =COUNTIF(Z10:AF10,"完了")/COUNTIF(R10:X10,"要") -> 1
A11: =A10+1 -> 1405 | B11: 41823 | C11: ADT | D11: CF | E11: 蔵光 | F11: 機械系 | G11: C/V | H11: 他拠点報告 | I11: \\172.18.154.188\adt_public\08_部門情報\8552_素板製造-設備技術\【設備技術修繕紀錄】\03機械\各窯情報資料\20140522 CF本線段ROLL停止--各窯橫展開2014.0606.xls | K11: ・CHAIN断裂異常 (2014/05/22) | L11: ・漏掉冷修後、初期伸長等的点検・確認 | M11: ・CHAIN鬆弛部位的可視化 | N11: 初回 | O11: 259 | P11: 5531 | R11: 要 | S11: 要 | T11: 要 | U11: 要 | V11: 要 | W11: - | X11: - | Y11: ・CHAIN鬆弛部位的可視化 ・LINE SHAFT駆動部的可視化 ※（2014/7/24追記） | Z11: 完了 | AA11: 完了 | AB11: 完了 | AC11: 完了 | AD11: 完了 | AE11: - | AF11: - | AG11: =IF(Y11="","","CLOSE") -> CLOSE | AH11: =IF(E11="","",IF(COUNTIF(Z11:AE11,"未")=0,"CLOSE","")) -> CLOSE | AI11: =COUNTIF(Z11:AF11,"完了")/COUNTIF(R11:X11,"要") -> 1
A12: =A11+1 -> 1406 | B12: 41823 | C12: ADT | D12: CF | E12: 蔵光 | F12: 機械系 | G12: C/V | H12: 他拠点報告 | I12: \\172.18.154.188\adt_public\08_部門情報\8552_素板製造-設備技術\【設備技術修繕紀錄】\03機械\各窯情報資料\20140522 CF本線段ROLL停止--各窯橫展開2014.0606.xls | K12: ・CHAIN断裂異常 (2014/05/22) | L12: ・漏掉冷修後、初期伸長等的点検・確認 | M12: ・CHAIN GUIDE的改造 | N12: 初回 | R12: 要 | S12: 要 | T12: 要 | U12: 要 | V12: 要 | W12: - | X12: - | Y12: ・CHAIN GUIDE的改造 | Z12: 完了 | AA12: 完了 | AB12: 完了 | AC12: 完了 | AD12: 完了 | AE12: - | AF12: - | AG12: =IF(Y12="","","CLOSE") -> CLOSE | AH12: =IF(E12="","",IF(COUNTIF(Z12:AE12,"未")=0,"CLOSE","")) -> CLOSE | AI12: =COUNTIF(Z12:AF12,"完了")/COUNTIF(R12:X12,"要") -> 1
A13: =A12+1 -> 1407 | B13: 41823 | C13: ADT | D13: EF | E13: 万代 | F13: 機械系 | G13: C/V | H13: 他拠点報告 | I13: ー | K13: ・増速SHAFT折損 | L13: ・強度不足 | M13: ・本線増速立起部的CV-Roll SHAFT材質由SS400 25φ變更為SCM435 40φ | N13: 再発 | O13: 120 | P13: 0 | R13: 要 | S13: 要 | T13: 要 | U13: 要 | V13: 要 | W13: - | X13: - | Y13: ・更換SHAFT材質変更的roll | Z13: 完了 | AA13: 完了 | AB13: 完了 | AC13: 完了 | AD13: 完了 | AE13: - | AG13: =IF(Y13="","","CLOSE") -> CLOSE | AH13: =IF(E13="","",IF(COUNTIF(Z13:AE13,"未")=0,"CLOSE","")) -> CLOSE | AI13: =COUNTIF(Z13:AF13,"完了")/COUNTIF(R13:X13,"要") -> 1 | AJ13: 方針CLOSE（冷修対応、来年費用など）
A14: =A13+1 -> 1408 | B14: 41827 | C14: ADT | D14: EF | E14: 鄭吉勝 | F14: 機械系 | G14: C/V | H14: 他拠点報告 | I14: ー | K14: 2Br増速C/V SHAFT破損異常 | L14: ・強度不足 | M14: ・由於現在R5加工的東西變為主流所以實施横展開。(入荷状況要確認） | N14: 再発 | P14: 2.8 | R14: 要 | S14: 要 | T14: 要 | U14: 要 | V14: 要 | W14: - | X14: - | Y14: ・更換為SHAFT材質変更的roll (個別駆動後連結駆動的第一支（増速No.5）→SCM435（shaft径維持現狀） 利用全窯工事日時進行更新) | Z14: 完了 | AA14: 完了 | AB14: 完了 | AC14: 完了 | AD14: 完了 | AE14: - | AF14: - | AG14: =IF(Y14="","","CLOSE") -> CLOSE | AH14: =IF(E14="","",IF(COUNTIF(Z14:AE14,"未")=0,"CLOSE","")) -> CLOSE | AI14: =COUNTIF(Z14:AF14,"完了")/COUNTIF(R14:X14,"要") -> 1 | AJ14: 方針CLOSE（冷修対応、来年費用など）
A15: =A14+1 -> 1409 | B15: 41809 | C15: ADT | D15: OFF切 | E15: 鄭吉勝 | F15: 電氣系 | G15: モーター | H15: 他拠点報告 | I15: 異常報告書（日文）共有フォルダ\其他\●AFK-OFF切#2LineX軸(電纜線焼毀)伺服機構異常-(C_E_J_K_Y_Z)CABLE Bear確認.xlsx | K15: X軸（電纜線燒毀）伺服機構異常 | L15: ・原因調查確認中！ | M15: ・電纜線的更換。 ・次回定修點檢確認 | N15: 初回 | O15: 165 | P15: 615 | R15: 要 | S15: 要 | T15: 要 | U15: 要 | V15: 要 | W15: 要 | X15: 要 | Y15: ・確認橫切機CABLEVEYOR 1.電纜線於CABLEVEYOR中排列是否整齊。 2.CABLEVEYOR中電纜線有無破損狀態。 3.CABLEVEYOR中電纜線有無皺摺或彎曲變形。 4.綑綁電纜線的線材（束帶）是否有斷掉。 | Z15: 完了 | AA15: 完了 | AB15: 完了 | AC15: 完了 | AD15: 完了 | AE15: 完了 | AF15: 完了 | AG15: =IF(Y15="","","CLOSE") -> CLOSE | AH15: =IF(E15="","",IF(COUNTIF(Z15:AE15,"未")=0,"CLOSE","")) -> CLOSE | AI15: =COUNTIF(Z15:AF15,"完了")/COUNTIF(R15:X15,"要") -> 1
A16: =A15+1 -> 1410 | B16: 41837 | C16: ADT | D16: YF | E16: 佐倉 曾志宏 | F16: 其它 | G16: C/V | H16: ADT内対応 | I16: ー | K16: PAD捲起造成板厚計波形異常 | L16: PAD的末端剥落 | M16: ・在PAD貼付作業標準書追加記載貼付方式的使用須知 ・在設備点検作業標準書的PAD点検部位追加關於剥落的內容 | N16: 再発 | O16: 0 | P16: 0 | R16: 要 | S16: 要 | T16: 要 | U16: 要 | V16: 要 | W16: - | X16: - | Y16: 讓整備班、三交代看一遍発生状況的資料，也在巡檢時讓他們看Br板厚計下PAD末端部是否有剥落狀況。 | Z16: 完了 | AA16: 完了 | AB16: 完了 | AC16: 完了 | AD16: 完了 | AE16: - | AF16: - | AG16: =IF(Y16="","","CLOSE") -> CLOSE | AH16: =IF(E16="","",IF(COUNTIF(Z16:AE16,"未")=0,"CLOSE","")) -> CLOSE | AI16: =COUNTIF(Z16:AF16,"完了")/COUNTIF(R16:X16,"要") -> 1
A17: =A16+1 -> 1411 | B17: 41838 | C17: ADT | D17: KF | E17: 鄭吉勝 | F17: 機械系 | G17: 循環 | H17: ADT内対応 | I17: 異常報告書（日文）共有フォルダ\其他\20140718 KF循環系CVキャリアROLL磨損橫展開連絡.xlsx | K17: KF循環系CV CARRIER ROLL磨損 | L17: ・碎玻璃或粉塵堆積 | M17: ・定期巡檢時發現CARRIER ROLL有碎玻璃堆積 立即依賴機械G協助掃除 ・制定聯絡的程序 | N17: 初回 | O17: 0 | P17: 0 | R17: 要 | S17: 要 | T17: 要 | U17: 要 | V17: 要 | W17: - | X17: - | Y17: ・CARRIER ROLL點檢對應流程說明。 ・ 對應作業步驟說明。 | Z17: 完了 | AA17: 完了 | AB17: 完了 | AC17: 完了 | AD17: 完了 | AE17: - | AF17: - | AG17: =IF(Y17="","","CLOSE") -> CLOSE | AH17: =IF(E17="","",IF(COUNTIF(Z17:AE17,"未")=0,"CLOSE","")) -> CLOSE | AI17: =COUNTIF(Z17:AF17,"完了")/COUNTIF(R17:X17,"要") -> 1
A18: =A17+1 -> 1412 | B18: 41824 | C18: AFK | D18: HF | E18: 浅原 | F18: 系統系 | G18: ACE | H18: ADT以外 | I18: 異常報告書（日文）共有フォルダ\其他\20140704HF ACE通信異常.xlsx | K18: ACE通信異常 | L18: LAN驅動程序問題 | M18: LAN驅動程序更新 | N18: 初回 | O18: 18 | P18: 0 | R18: 要 | S18: - | T18: - | U18: - | V18: - | W18: - | X18: - | Y18: LAN驅動程序更新。 8/11再発。対策未定。 | Z18: 完了 | AA18: - | AB18: - | AC18: - | AD18: - | AE18: - | AF18: - | AG18: =IF(Y18="","","CLOSE") -> CLOSE | AH18: =IF(E18="","",IF(COUNTIF(Z18:AE18,"未")=0,"CLOSE","")) -> CLOSE | AI18: =COUNTIF(Z18:AF18,"完了")/COUNTIF(R18:X18,"要") -> 1
A19: =A18+1 -> 1413 | B19: 41836 | C19: ADT | D19: CF | E19: 俊良 | F19: 機械系 | G19: C/V | H19: 他拠点報告 | I19: 異常報告書（日文）共有フォルダ\其他\20140716CF RB採板CV7 ベアリング異常.xlsx | K19: BEARING破損異常 | L19: ・RB LINE的CV点検作業有在定期項目中，雖然有進行点検但是從 安全柵欄外以目視点検，所以沒能発現 | M19: ・点検頻度変更（点検無し→ＪＣ時/工事日点検） ・該部位的可視化 | N19: 初回 | O19: 90 | P19: 50 | R19: - | S19: 要 | T19: 要 | U19: - | V19: - | W19: - | X19: - | Y19: 等待設技見解（CF預定進行BEARING2層化的測試 ～8/末） | Z19: - | AA19: 完了 | AB19: 完了 | AC19: - | AD19: - | AE19: - | AF19: - | AG19: =IF(Y19="","","CLOSE") -> CLOSE | AH19: =IF(E19="","",IF(COUNTIF(Z19:AE19,"未")=0,"CLOSE","")) -> CLOSE | AI19: =COUNTIF(Z19:AF19,"完了")/COUNTIF(R19:X19,"要") -> 1
A20: =A19+1 -> 1414 | B20: 41856 | C20: ADT | D20: ZF | E20: 炳興 | F20: 電氣系 | G20: 循環 | H20: ADT内対応 | I20: 異常報告書（日文）共有フォルダ\其他\20140805 ZF包裝循環4 CULLET BC SLIP異常報告.xlsx | K20: 上游軸承部Slip Sensor感度不良 | L20: 1.Sensor處玻璃粉塵堆積 2.Sensor感應位置不佳 | M20: 1.工事日定期清掃(清掃頻度討論待) 2.工事日全數Sensor感應距離確認(8/14) | N20: 初回 | O20: 0 | P20: 0 | R20: 要 | S20: 要 | T20: 要 | U20: 要 | V20: 要 | W20: - | X20: - | Y20: 1.工事日定期清掃(清掃頻度討論待) 2.工事日全數Sensor感應距離確認(8/14) | Z20: 完了 | AA20: 完了 | AB20: 完了 | AC20: 完了 | AD20: 完了 | AE20: - | AF20: - | AG20: =IF(Y20="","","CLOSE") -> CLOSE | AH20: =IF(E20="","",IF(COUNTIF(Z20:AE20,"未")=0,"CLOSE","")) -> CLOSE | AI20: =COUNTIF(Z20:AF20,"完了")/COUNTIF(R20:X20,"要") -> 1
A21: =A20+1 -> 1415 | B21: 41822 | C21: 高砂 | D21: GF | E21: 浅原 | F21: 機械系 | G21: C/V | H21: ADT以外 | I21: 異常報告書（中文）共有フォルダ\201408以降\20140702GF B-LINE FT部引込CV驅動鏈條斷裂.xls | K21: 駆動CHAIN接頭部破損 | L21: 接頭的定期更換延遅 | M21: 徹底實施定期更換，使用CHAIN更換清冊。 | N21: 初回 | O21: 0 | P21: 161 | R21: 要 | S21: 要 | T21: 要 | U21: 要 | V21: 要 | W21: 要 | X21: - | Y21: 日常点検、週末点検、工事日点検、異常時交換。檢討導入自動給油器(SIMALUBE)。實施1回/半年的定修。CHAIN更換記録以管理清冊作管理。 | Z21: 完了 | AA21: 完了 | AB21: 完了 | AC21: 完了 | AD21: 完了 | AE21: 完了 | AF21: - | AG21: =IF(Y21="","","CLOSE") -> CLOSE | AH21: =IF(E21="","",IF(COUNTIF(Z21:AE21,"未")=0,"CLOSE","")) -> CLOSE | AI21: =COUNTIF(Z21:AF21,"完了")/COUNTIF(R21:X21,"要") -> 1
A22: =A21+1 -> 1416 | B22: 41841 | C22: ADT | D22: JF | E22: 峯謀 | F22: 電氣系 | G22: 採板設備 | H22: ADT内対応 | I22: 異常報告書（中文）共有フォルダ\201407\20140721JF 採板ROBOT制御盤電源異常.xls | K22: 因對應瞬停用UPS的故障造成電源装置的保險絲破損，使得電源無法開啟。 | L22: UPS基板內部的電容器因為長時間過電壓。溫度過高的關係.電容器絕緣失效爆裂.導致UPS故障。 | M22: ・UPS内、電容器耐電圧規格的変更請依賴業者進行更換。以更換後的部分來進行測試，如果沒有問題的話，就依序更換電容器。 ・如果電容器更換前再次發生異常的話，以不會影響UPS電源的配線變更做対応。 | N22: 初回 | O22: 5 | P22: 106 | R22: - | S22: 要 | T22: 要 | U22: 要 | V22: 要 | W22: 要 | X22: - | Y22: 1.電氣測試中.待判定OK後將陸續展開交換作業。 | Z22: - | AA22: 完了 | AB22: 完了 | AC22: 完了 | AD22: 完了 | AE22: 完了 | AF22: - | AG22: =IF(Y22="","","CLOSE") -> CLOSE | AH22: =IF(E22="","",IF(COUNTIF(Z22:AE22,"未")=0,"CLOSE","")) -> CLOSE | AI22: =COUNTIF(Z22:AF22,"完了")/COUNTIF(R22:X22,"要") -> 1 | AJ22: →最終評価はいつまでに出すの？それを決めないと進まない！！ →最終評価は電気G周さんよりOKとの連絡有り。 →J/K冷修導入横展開スケジュール計画有り。(指摘修繕計畫列入)一時CLOSE
A23: =A22+1 -> 1417 | B23: 41863 | C23: AFK | D23: FF | E23: 三路 | F23: 機械系 | G23: P詰め機 | H23: ADT以外 | I23: 異常報告書（中文）共有フォルダ\201408以降\20140805_AFK_FF_PL ChangerPL空PL衝突異常.xls | K23: 実際PL搬送用伺服的馬達連軸器的KEY脱落，造成実際PL搬送的停止位置偏移。 | L23: 連軸器的KEY脱落 | M23: ・KEY加工変更（AFK詢問中？） ・在実際PL搬送（払出側）追加停止位置確認PR | N23: 初回 | O23: 13 | P23: 350 | R23: - | S23: 要 | T23: 要 | U23: 要 | V23: - | W23: - | X23: - | Y23: ・機械G点検後檢討対策 ・在実際PL搬送（払出側）追加停止位置確認PR | Z23: - | AA23: 完了 | AB23: 完了 | AC23: 完了 | AD23: - | AE23: - | AF23: - | AG23: =IF(Y23="","","CLOSE") -> CLOSE | AH23: =IF(E23="","",IF(COUNTIF(Z23:AE23,"未")=0,"CLOSE","")) -> CLOSE | AI23: =COUNTIF(Z23:AF23,"完了")/COUNTIF(R23:X23,"要") -> 1
A24: =A23+1 -> 1418 | B24: 41854 | C24: AFK | D24: TAS | E24: 浅原 | F24: 電氣系 | G24: C/V | H24: ADT以外 | I24: 異常報告書（中文）共有フォルダ\201408以降\20140803 Glass檢知Senser異常.xls | J24: 異常報告書（中文）共有フォルダ\201408以降\20140803 Glass檢知Senser異常.xls | K24: 基板檢查結束後, 未正常移載至採板側, Though (直接通過)造成廢棄Loss（1枚）。之後還是間斷出現Though廢棄, 於是Line停機並呼出設技。 | L24: 就解決了, 所以原因推測為反射板或Senser起霧的關係。 | M24: 持續工事日定期點檢掃除。 | N24: 初回 | O24: 38 | P24: 218 | R24: 要 | S24: 要 | T24: 要 | U24: 要 | V24: 要 | W24: 要 | X24: 要 | Y24: 定期地清掃傳感器。 定期地調整傳感器的靈敏度。 | Z24: 完了 | AA24: 完了 | AB24: 完了 | AC24: 完了 | AD24: 完了 | AE24: 完了 | AF24: 完了 | AG24: =IF(Y24="","","CLOSE") -> CLOSE | AH24: =IF(E24="","",IF(COUNTIF(Z24:AE24,"未")=0,"CLOSE","")) -> CLOSE | AI24: =COUNTIF(Z24:AF24,"完了")/COUNTIF(R24:X24,"要") -> 1
A25: =A24+1 -> 1419 | B25: 41837 | C25: AFK | D25: TAS | E25: 浅原 | F25: 機械系 | G25: 真空Pump | H25: ADT以外 | I25: 異常報告書（中文）共有フォルダ\201407\20140717GUT OFF切NO1真空P力異常.xls | J25: ..\..\異常報告書(中文)\201407\●AFK-GUT OFF切#1真空Pump壓力異常-(C_E_J_K_Y_Z)真空Pump確認.xls | K25: 發生Glass吸著異常発生。真空Pump 由原本使用的#1切替到 #1#2同時使用，也無良化。切替至真空Pump#2單獨使用後 異常才解除。 | L25: 碳片出現部分破損導致壓力低下。推測碳片的磨耗致使失衡, 並發生碳片破損。 | M25: 更換真空Pump #1（7/18實施）。將真空Pump 安全柵内⇒安全柵外 以利保養。改善更換作業性（7/21完成）。檢討定期更換等預防措施可行性 | N25: 初回 | O25: 143 | P25: 554 | R25: 要 | S25: 要 | T25: 要 | U25: 要 | V25: 要 | W25: 要 | X25: 要 | Y25: 確認真空泵的檢查記錄。 確認真空泵的交換記錄。 確認真空泵的設置位置。 | Z25: 完了 | AA25: 完了 | AB25: 完了 | AC25: 完了 | AD25: 完了 | AE25: 完了 | AF25: 完了 | AG25: =IF(Y25="","","CLOSE") -> CLOSE | AH25: =IF(E25="","",IF(COUNTIF(Z25:AE25,"未")=0,"CLOSE","")) -> CLOSE | AI25: =COUNTIF(Z25:AF25,"完了")/COUNTIF(R25:X25,"要") -> 1
A26: =A25+1 -> 1420 | B26: 41843 | C26: ADT | D26: ZF | E26: 浅原 | F26: 檢查系 | G26: 精査 | H26: ADT内対応 | I26: 異常報告書（中文）共有フォルダ\201408以降\複本 20140723ZF 精査ｼﾝｸﾗｲｱﾝﾄ用HUB異常報告.xls | K26: 精査thin client異常。T/P畫面上顯示『remote esktop 沒有接上 remote computer』重新啟動精査判定SERVER,但無法登入。因為精査thin client用的HUB LED 燈號熄滅所以拔掉HUB的電源線後重新插上就回復正常了。之後異常就沒再發生過了。 | L26: ①推測是HUB的電源線鬆脫。 ②重要的檢查機附帶設備的維持管理不足。 | M26: 原因①的對策 固定好HUB電源線,使其不鬆脫。 變更HUB的電源設置位置。 原因②的對策 實施詳查室的處理整頓。 為整備班的檢查表追加HUB確認項目。 | N26: 初回 | O26: 6 | P26: 112 | R26: 要 | S26: 要 | T26: 要 | U26: 要 | V26: 要 | W26: 情報 | X26: 情報 | Y26: 固定好HUB電源線,使其不鬆脫。 變更HUB的電源設置位置。 實施詳查室的處理整頓。 為整備班的檢查表追加HUB確認項目。 | Z26: 完了 | AA26: 完了 | AB26: 完了 | AC26: 完了 | AD26: 完了 | AE26: - | AF26: - | AG26: =IF(Y26="","","CLOSE") -> CLOSE | AH26: =IF(E26="","",IF(COUNTIF(Z26:AE26,"未")=0,"CLOSE","")) -> CLOSE | AI26: =COUNTIF(Z26:AF26,"完了")/COUNTIF(R26:X26,"要") -> 1
A27: =A26+1 -> 1421 | B27: 41857 | C27: AFK | D27: IF | E27: 浅原 | F27: 機械系 | G27: C/V | H27: ADT以外 | I27: 異常報告書（中文）共有フォルダ\201408以降\20140806IF 本線CVロールシャフトエンドプレート脱落異常(中文).xls | K27: 巡檢發現到，本線CV Roll#238的驅動側，防止sprocket key鬆脫的end plate脫落，sprocket外移了10mm左右。呼出設備技術，Guillotine處理開始。修復完成。Guillotine解除。F1採版開始 | L27: 冷修時的旋緊不足。因roll的連續回轉的震動，螺絲鬆脫、掉落。現在使用Nord-Lock墊圈的緣故，如果正確地鎖好的話，不太可能輕易地就鬆脫。 | M27: 下次工事日時增強旋緊度 （在工事日之前，從點檢窗做目視點檢） | N27: 再発 | O27: 35 | P27: 952 | R27: 情報 | S27: 情報 | T27: 情報 | U27: 情報 | V27: 情報 | W27: 情報 | X27: 情報 | Y27: 工事日時、檢查實施。增強旋緊度。 能看見的化。 使用Nord-Lock墊圈。 8/6再発、対策未定。 | Z27: - | AA27: - | AB27: - | AC27: - | AD27: - | AE27: - | AF27: - | AG27: =IF(Y27="","","CLOSE") -> CLOSE | AH27: =IF(E27="","",IF(COUNTIF(Z27:AE27,"未")=0,"CLOSE","")) -> CLOSE | AI27: =COUNTIF(Z27:AF27,"完了")/COUNTIF(R27:X27,"要") -> #DIV/0!
A28: =A27+1 -> 1422 | B28: 41859 | C28: AFK | D28: LF | E28: 浅原 | F28: 機械系 | G28: C/V | H28: ADT以外 | I28: 異常報告書（中文）共有フォルダ\201408以降\20140808LF 本線増速No 4No 5共用惰輪(Idler)固定Plate折損.xls | K28: 製造三交代發現惰輪Idler出現晃動情形。呼出設技機械Team, 確認時發現惰輪Ider的固定Plate折損。（雖然整個斷掉了, 但是沒有脫落還是一直回轉。）開啟Guillotine該處實施焊接補強生産再開 | L28: 増速C/V＃4減速及＃5加速時、推測負荷集中在該處的惰輪Idler而斷裂。同樣規格的惰輪Idler目前使用在増速C/V＃5＃6間、増速C/V＃6＃7間、仍追加一片Plate並進行了焊接補強（LF建設時） | M28: 緊急對應內側追加一片Plate並進行焊接補強對策製作一整片的新的Plate、於下回工事日進行設置 | N28: 初回 | O28: 60 | P28: 1234 | R28: - | S28: - | T28: - | U28: - | V28: 要 | W28: - | X28: - | Y28: KF 本線№4 C/V。 Idler軸的材質變更為SCM435。 （利用冷修工事進行） | Z28: - | AA28: - | AB28: - | AC28: - | AD28: 完了 | AE28: - | AF28: - | AG28: =IF(Y28="","","CLOSE") -> CLOSE | AH28: =IF(E28="","",IF(COUNTIF(Z28:AE28,"未")=0,"CLOSE","")) -> CLOSE | AI28: =COUNTIF(Z28:AF28,"完了")/COUNTIF(R28:X28,"要") -> 1
A29: =A28+1 -> 1423 | B29: 41855 | C29: 高砂 | D29: GF | E29: 浅原 | F29: 電氣系 | G29: A/K | H29: ADT以外 | I29: 異常報告書（中文）共有フォルダ\201408以降\20140804 GF B-LINE洗浄機Air_Knife_INV異常.xls | K29: B-LINE洗浄機Air_Knife_INV異常発生(2Br全採中, 因此無Loss)Thermal(積熱繼電器)跳脫無法復歸, 因此呼出設技實施Blower更換B-LINE刮傷檢查後開始採板 | L29: Blower_Motor過熱融解導致Bearing卡住、再加上Motor的熱度影響到 Motor冷却用Fan的樹脂Blade(葉片)融解※GF1 ON-TAS Start時(2008年～)起持續使用。 無更換& Overhaul(大檢修)。 | M29: ・毎月工事日更換2台備品, 並依序實施 Overhaul(大檢修)。(※9台+預備2台 約需4個月可全數更換) | N29: 初回 | O29: 0 | P29: 0 | R29: - | S29: - | T29: - | U29: 要 | V29: 要 | W29: 要 | X29: 要 | Y29: 並依序實施 Overhaul。 （設備技術相談待） ADT OFF-TAS・・・1回/3年 ON-TAS・・・1回/冷修 | Z29: - | AA29: - | AB29: - | AC29: 完了 | AD29: 完了 | AE29: 完了 | AF29: 完了 | AG29: =IF(Y29="","","CLOSE") -> CLOSE | AH29: =IF(E29="","",IF(COUNTIF(Z29:AE29,"未")=0,"CLOSE","")) -> CLOSE | AI29: =COUNTIF(Z29:AF29,"完了")/COUNTIF(R29:X29,"要") -> 1
A30: =A29+1 -> 1424 | B30: 41851 | C30: AFK | D30: TAS | E30: 浅原 | F30: 電氣系 | G30: 水處理場電源供應器 | H30: ADT以外 | I30: 異常報告書（中文）共有フォルダ\201408以降\20140731GUT GUT水處理場電源供應器停止異常.xls | K30: 於GUT全產線純水發生桶槽缺水預報及缺水警報、產線依序停止。由於水處理場制御盤警報畫面之2B3T №2 PUMP有出現停止警報（№1PUMP稼働）、因此呼出設技。由於洗滌器的電源是由FF窯供給的，因此沒有停止。以臨時電源來讓純水桶槽得以往產線供給（生産再開）。制御盤内之電源供應器（1台）確認故障、更換為予備品。設備復舊。 | L30: 由於主電源的制御盤電源發生停止因此警報沒能響起。由於使用壽命可達10年因此未進行更換。（DF：GUT 2005年8月量産開始）由於緊急用的純水Back Up供給手順未能準備妥當因此耽擱到生産之再開。 | M30: 8/24 伴隨著DF3的冷修工事計劃於停電時將水處理場的電源供應器進行全數更換。其他、關於各產線之制御電源計畫藉由明年度的起業申請、依序進行更換。關於水處理場的警報因為對於人體、環境都有很顯著的影響、有依賴希望能從上位階層來發報，但得到的回覆是說很困難。（於設技再進行檢討） | N30: 初回 | O30: 0 | P30: 344 | R30: 要 | S30: 要 | T30: 要 | U30: 要 | V30: 要 | W30: 要 | X30: - | Y30: 重要的設備的電源供應器。 計劃地更新。 協議設技決定。 ※橫(側)展開連決定在擔當者會議上協議電G更新哪個設備。 2014/10/8 各設備のDC電源装置について、「優先順位」・「交換頻度」のリストを各ライン毎に電気Gが作成中。 | Z30: 完了 | AA30: 完了 | AB30: 完了 | AC30: 完了 | AD30: 完了 | AE30: 完了 | AF30: - | AG30: =IF(Y30="","","CLOSE") -> CLOSE | AH30: =IF(E30="","",IF(COUNTIF(Z30:AE30,"未")=0,"CLOSE","")) -> CLOSE | AI30: =COUNTIF(Z30:AF30,"完了")/COUNTIF(R30:X30,"要") -> 1
A31: =A30+1 -> 1425 | B31: 41857 | C31: AFK | D31: IF | E31: 浅原 | F31: 機械系 | G31: C/V | H31: ADT以外 | I31: 異常報告書（中文）共有フォルダ\201408以降\20140806IF 本線CVロールシャフトエンドプレート脱落異常(中文).xls | K31: 巡檢時發現本線増速CV_Roll驅動側防止Sprocket_Key脫落的End_Plate上面的兩支固定螺栓有一支已經脱落了、剩下一支也快要脱落了、Plate呈現不夠穩固的狀態。和上次的Roll同一支。※上午巡檢的部分確認沒有問題。呼出設技、開啟Guillotine H/O捨板處理。這次使用樂泰( LOCTITE) 來固定螺栓。復歸結束後。F1採板開始。 | L31: 上回在8/6發生時、以確實進行螺栓増締鎖緊的對策、 再加上使用的已經是Nord-Lock的華司、但是螺栓還是鬆掉了。 原因調査中。 | M31: 【緊急對策】 使用樂泰( LOCTITE) 來固定螺栓。 （包含同様的發生位置、持續由點檢口進行目視點檢） 【恒久對策】 現段階未決定。原因調査中。 | R31: 情報 | S31: 情報 | T31: 情報 | U31: 情報 | V31: 情報 | W31: 情報 | X31: 情報 | Y31: 再発。原因不明。対策未定。 | Z31: - | AA31: - | AB31: - | AC31: - | AD31: - | AE31: - | AF31: - | AG31: =IF(Y31="","","CLOSE") -> CLOSE | AH31: =IF(E31="","",IF(COUNTIF(Z31:AE31,"未")=0,"CLOSE","")) -> CLOSE | AI31: =COUNTIF(Z31:AF31,"完了")/COUNTIF(R31:X31,"要") -> #DIV/0!
A32: =A31+1 -> 1426 | B32: 41862 | C32: AFK | D32: HF | E32: 浅原 | F32: 系統系 | G32: ACE | H32: ADT以外 | I32: 異常報告書（中文）共有フォルダ\201408以降\20140811HF ACE通信異常（再）.xls | K32: ACE通信異常 | L32: 懷疑PC內藏LAN CARD的能力不足。 | M32: 擴張型NIC(LAN CARD)變更預定。 | N32: 再発 | O32: 0 | P32: 0 | R32: 情報 | S32: - | T32: - | U32: - | V32: - | W32: - | X32: - | Y32: 再発。 AFKの対策としては、擴張型NIC(LAN CARD)變更。 ★ADT内のSiemens製PCでは発生していない事と（個体不良の疑い）、発生原因が特定出来ていない事から、ADTでは「情報」のみとする。（ADT電気） | Z32: - | AA32: - | AB32: - | AC32: - | AD32: - | AE32: - | AF32: - | AG32: =IF(Y32="","","CLOSE") -> CLOSE | AH32: =IF(E32="","",IF(COUNTIF(Z32:AE32,"未")=0,"CLOSE","")) -> CLOSE | AI32: =COUNTIF(Z32:AF32,"完了")/COUNTIF(R32:X32,"要") -> #DIV/0!
A33: =A32+1 -> 1427 | B33: 41849 | C33: AFK | D33: HF | E33: 三路 | F33: 電氣系 | G33: C/V | H33: ADT以外 | I33: 異常報告書（中文）共有フォルダ\201407\20140719HF 2Br紙巻CV驅動伺服馬達過負荷停止異常-中文.xls | K33: 紙巻C/V因伺服異常（過負荷）而停止。即使更換Motor・Amp・Relay・DC電源装置也沒有良化。※在Motor単体下負荷率低沒有發生異常。將伺服的Tuning模式由AUTO變更為MANUAL後良化。 | L33: 由於Motor単独運転下負荷率低，所以假定是滾輪、惰輪的軸承劣化等機械性的要因。再加上Motor的Tuning模式為AUTO Tuning，所以累積負荷率造成異常。 | M33: Tuning模式由AUTO變更為MANUAL。 | N33: 初回 | O33: 0 | P33: 0 | R33: - | S33: - | T33: - | U33: - | V33: - | W33: - | X33: - | Y33: 因為AFK沒有找出根本的原因（為何負荷會變高?），所以ADT的方針就是什麼都不要做。 先看看伺服的AUTO Tuning的負荷状態再來應對。 雖然認為伺服馬達的負荷上好像有什麼大的負荷変動，但最終卻什麼都沒有發現。 擔心同様的事件時做MANUAL的設定是比較有利，但是負荷漸漸加重時AUTO則比較有利。 | Z33: - | AA33: - | AB33: - | AC33: - | AD33: - | AE33: - | AF33: - | AG33: =IF(Y33="","","CLOSE") -> CLOSE | AH33: =IF(E33="","",IF(COUNTIF(Z33:AE33,"未")=0,"CLOSE","")) -> CLOSE | AI33: =COUNTIF(Z33:AF33,"完了")/COUNTIF(R33:X33,"要") -> #DIV/0!
A34: =A33+1 -> 1428 | B34: 41878 | C34: ADT | D34: JF | E34: 三路 | F34: 電氣系 | G34: 縦切機 | H34: ADT内対応 | I34: 異常報告書（中文）共有フォルダ\201408以降\20140827JF №1縦切機停止異常.xls | K34: 採板中由於Frame上昇，造成沒有縦切線。另外也無法做TP的操作。 ※沒有發出異常警報 | L34: Frame上昇・無法操作TP的原因 ・由於PLC不知是什麼原因造成停止。 沒有異常警報的原因 ・由於PLC停止造成警報無法出力。 | M34: ・雜訊対策検討中（ADT電気） ・改造成以本線Master PLC來監視縦切機PLC，當PLC異常時由本線Master PLC來發出警報的soft。 | N34: 初回 | O34: 9 | P34: 172 | R34: 要 | S34: 要 | T34: 要 | U34: 要 | V34: 要 | W34: - | X34: - | Y34: 改造成即使在縦切機PLC發生異常時也能夠發出警報的soft。 | Z34: 完了 | AA34: 完了 | AB34: 完了 | AC34: 完了 | AD34: 完了 | AE34: - | AF34: - | AG34: =IF(Y34="","","CLOSE") -> CLOSE | AH34: =IF(E34="","",IF(COUNTIF(Z34:AE34,"未")=0,"CLOSE","")) -> CLOSE | AI34: =COUNTIF(Z34:AF34,"完了")/COUNTIF(R34:X34,"要") -> 1 | AJ34: 方針CLOSE（KF/冷修中対応）←12/30完了
A35: =A34+1 -> 1429 | B35: 41881 | C35: ADT | D35: CF | E35: 蔵光 | F35: 機械系 | G35: SMAP | H35: ADT内対応 | I35: 異常報告書（中文）共有フォルダ\201408以降\20140830CF L側SMAP動作異常.xls | K35: 三交代聯絡L側SMAP動作異常。整備進行確認懷疑電磁閥損壞，聯絡電氣機械進行對應。三交代協助耳部拿取，進行電磁閥更換。更換完畢經過動作測試與採板測試異常再發。將氣壓缸32號潤滑油開啟後，進行動作測試。測試OK，恢復SMAP採板。觀察無再發。 | L35: 更換電磁閥後異常再發。進行32號潤滑油的給油調整後，動作異常良化。此處氣壓缸潤滑油平時是關閉沒有使用的狀態。因此造成此次氣壓缸潤滑不足進而造成SMAP動作異常。不使用的理由是在消音器的出風口會有油汙噴濺的可能。會有品質上的疑慮。 | M35: 更換電磁閥與開啟32號潤滑油 (暫時對應-機械、電氣)。改善32號潤滑油使用方式。平時不使用=>1次/2週 (每次開啟8小時) (頻度可再檢討)電磁閥消音器使用吸油棉包覆防止潤滑油噴濺。 | N35: 初回 | O35: 0 | P35: 113 | R35: - | S35: 要 | T35: 要 | U35: 要 | V35: 要 | W35: - | X35: - | Y35: ①於整備日常點檢表追記 Lubricator給油器相關管理項目（Oil殘量、開度Dial數値、給油）。 ②教育整備人員Lubricator給油器的作用。 ③設置Lubricator給油器的設備需全數設置Exhaust Cleaner （油霧回収機器）。（ADT全窯）（對象設備）本線SMAP、本線GATE_Shutter、FT/引入/BB PAD部。 | Z35: - | AA35: 完了 | AB35: 完了 | AC35: 完了 | AD35: 完了 | AE35: - | AF35: - | AG35: =IF(Y35="","","CLOSE") -> CLOSE | AH35: =IF(E35="","",IF(COUNTIF(Z35:AE35,"未")=0,"CLOSE","")) -> CLOSE | AI35: =COUNTIF(Z35:AF35,"完了")/COUNTIF(R35:X35,"要") -> 1 | AJ35: Y/Eはどうするの？ →YF確認中。 →EFは2Brのみ残っている。（12月中に完了させます。）
A36: =A35+1 -> 1430 | B36: 41880 | C36: AFK | D36: HF | E36: 三路 | F36: 機械系 | G36: 紙巻機 | H36: ADT以外 | I36: 異常報告書（中文）共有フォルダ\201408以降\20140821HF IZUMI産業製 紙巻機切刀上刃LM_Guide固定螺栓折損異常.xls | K36: 由於Cutter的紙切不良進行點檢時，發現將Cutter的上刀刃固定在LM Guide處的螺栓折損。由於螺栓更換2天後還是發生同様的異常，因此做Cutter Unit的更換。 | L36: 一直以來，上刀刃和下刀刃的上下是以下刀刃側的Liner調整，由於下刀刃的調整量已經用盡，因此在上刀刃側LM Guide處加入Liner做調整，造成Cylinder Piston(汽缸活塞)的負荷。 | M36: ・發現左右Cylinder的昇降時間點有明顯錯開時，就進行Cylinder点検而不要勉強去調整。 ・關於Cutter的紙切，下刀刃的調整量用盡時，就做Cutter Unit本体的更換。 | N36: 初回 | O36: 0 | P36: 0 | R36: - | S36: - | T36: - | U36: 要 | V36: 要 | W36: 要 | X36: - | Y36: ・下次工事日進行CYL及LM Guide的点検。 ・点検後Cutter昇降動作如果有異常的話，請依賴機械做CYL的確認，製造方面不要勉強去做調整。 | Z36: - | AA36: - | AB36: - | AC36: 完了 | AD36: 完了 | AE36: 完了 | AF36: - | AG36: =IF(Y36="","","CLOSE") -> CLOSE | AH36: =IF(E36="","",IF(COUNTIF(Z36:AE36,"未")=0,"CLOSE","")) -> CLOSE | AI36: =COUNTIF(Z36:AF36,"完了")/COUNTIF(R36:X36,"要") -> 1
A37: =A36+1 -> 1431 | B37: 41884 | C37: ADT | D37: EF | E37: 万代 | F37: 機械系 | G37: 採板設備 | H37: ADT内対応 | I37: 異常報告書（中文）共有フォルダ\201408以降\20140902EF 6P採板RB紙掴みシリンダー異常rev.1.xls | K37: 6:24 6POS 採板ROBOT發生紙抓動作異常。6:30 切替2Bｒ全採。6:40 確認到6POS左上紙抓CYL脫落。呼出整備。7:10 6POS左上部 紙抓CYL交換作業開始。7:40 CYL更換後、進行試板流及CYL動作速度調整。8:15 1Bｒ恢復全採 | M37: 壓力設定在0.13Mpa。預定變更CYL型式 MGPL12→MGPM12(額定扭矩up） | N37: 再発 | O37: 6 | P37: 29 | R37: - | S37: 要 | T37: 要 | U37: - | V37: 要 | W37: - | X37: - | Y37: 壓力設定在0.13Mpa。預定變更CYL型式 MGPL12→MGPM12(額定扭矩up）(結論）0.20Mpaで使用することでCLOSE | Z37: - | AA37: 完了 | AB37: 完了 | AC37: - | AD37: 完了 | AE37: - | AF37: - | AG37: =IF(Y37="","","CLOSE") -> CLOSE | AH37: =IF(E37="","",IF(COUNTIF(Z37:AE37,"未")=0,"CLOSE","")) -> CLOSE | AI37: =COUNTIF(Z37:AF37,"完了")/COUNTIF(R37:X37,"要") -> 1
A38: =A37+1 -> 1432 | B38: 41892 | C38: ADT | D38: YF | E38: 仕明 | F38: 機械系 | G38: SMAP | H38: ADT内対応 | I38: 異常報告書（中文）共有フォルダ\201408以降\20140910 YF 包裝 R側 SMAP異常報告書.xls | K38: 時規皮帶劣化，導致作動不良 | M38: 1.進行L側SMAP時規皮帶及調速閥點檢(橫展開)。2.平時SMAP作動速度發生變化時立即進行調整，若無法調整連絡機械人員進行確認 3.CYLINDER交換時連同調速閥也一倂更換 | N38: 初回 | O38: 3 | P38: 92 | R38: 要 | S38: 要 | T38: 要 | U38: 要 | V38: 要 | W38: - | X38: - | Y38: 1.進行L側SMAP時規皮帶及調速閥點檢(橫展開)。2.平時SMAP作動速度發生變化時立即進行調整，若無法調整連絡機械人員進行確認 3.CYLINDER更換時連同調速閥也一倂更換 | Z38: 完了 | AA38: 完了 | AB38: 完了 | AC38: 完了 | AD38: 完了 | AE38: - | AF38: - | AG38: =IF(Y38="","","CLOSE") -> CLOSE | AH38: =IF(E38="","",IF(COUNTIF(Z38:AE38,"未")=0,"CLOSE","")) -> CLOSE | AI38: =COUNTIF(Z38:AF38,"完了")/COUNTIF(R38:X38,"要") -> 1
A39: =A38+1 -> 1433 | B39: 41889 | C39: 高砂 | D39: OFF切 | E39: 三路 | F39: 機械系 | G39: C/V | H39: ADT以外 | I39: 異常報告書（中文）共有フォルダ\201408以降\20140907TDS2 搬送異常Trouble報告.xls | J39: O:\00 製造一部共通\横展開確認\設備異常報告\異常報告書(日文)\201408以降\ADT OFF切機擴出CV驅動惰輪.xls | K39: 由於皮帶摩耗 導致鐵絲呈現外露状態 因此進行皮帶更換。由於搬送皮帶偏移到Pulley突出部位的上方、因接觸而摩耗 | M39: 做為預防措置、確認皮帶摩耗状態時若發現偏移狀況、需隨時進行Pulley的對芯調整 | N39: 初回 | O39: 180 | P39: 0 | R39: - | S39: - | T39: - | U39: - | V39: - | W39: - | X39: 要 | Y39: 做為預防措置、確認皮帶摩耗状態時若發現偏移狀況、需隨時進行Pulley的對芯調整 | Z39: - | AA39: - | AB39: - | AC39: - | AD39: - | AE39: - | AF39: 完了 | AG39: =IF(Y39="","","CLOSE") -> CLOSE | AH39: =IF(E39="","",IF(COUNTIF(Z39:AE39,"未")=0,"CLOSE","")) -> CLOSE | AI39: =COUNTIF(Z39:AF39,"完了")/COUNTIF(R39:X39,"要") -> 1
A40: =A39+1 -> 1434 | B40: 41875 | C40: 高砂 | D40: TAS | E40: 三路 | F40: 機械系 | G40: 紙巻機 | H40: ADT以外 | I40: 異常報告書（中文）共有フォルダ\201408以降\20140824GUT GUT3紙機送紙偏移異常.xls | K40: 因出紙皮帶Servo Amp（過負荷）而發生異常停止。確認驅動部時發現馬達温度異常升高。 | L40: 確認到№1、№7 皮帶（兩端）偏移並接觸到側邊的護蓋、引起馬達過負載。 | M40: 與設技檢討中 | N40: 初回 | O40: 160 | P40: 2697 | R40: - | S40: - | T40: - | U40: 要 | V40: 要 | W40: 要 | X40: - | Y40: 進行異常報告書的互閱，並針對紙排出Belt的伺服有過負荷異常時及紙有傾斜被捲的状況時，教育現場人員可能是送紙Belt發生偏移。 | Z40: - | AA40: - | AB40: - | AC40: 完了 | AD40: 完了 | AE40: 完了 | AF40: - | AG40: =IF(Y40="","","CLOSE") -> CLOSE | AH40: =IF(E40="","",IF(COUNTIF(Z40:AE40,"未")=0,"CLOSE","")) -> CLOSE | AI40: =COUNTIF(Z40:AF40,"完了")/COUNTIF(R40:X40,"要") -> 1
A41: =A40+1 -> 1435 | B41: 41877 | C41: AFK | D41: TAS | E41: 三路 | F41: 電氣系 | G41: 移載設備 | H41: ADT以外 | I41: 異常報告書（中文）共有フォルダ\201408以降\20140826GUT OFF切3上流移載機異常.xls | K41: 中班在進行事前準備時, 進行設備運轉, 並投入刮傷檢查用的樣品, 此時, 上流側№1移載機（Master、Slave兩者）Servo發生異常無法復歸, 因此呼出設技（電氣T）。 | L41: 計畫於OFF切№1～№3『搬送C/V相關參數變更』並進行作業。由於OFF切№1及2是在生産中實施的, 變更後也無設備上的異常。原本打算№3也同様要重寫『搬送C/V參數』,但是誤操作變更了上流№1移載機（Splave側）的參數。此重寫作業並未事先聯絡製造, 另外因為產線計畫停止中,所以沒有確認動作就結束此作業。 | M41: 因為PLC Soft裡面有同様的回路, 導致誤操作, 變更了移載機的參數, 為了防止弄錯 軸No.的位置, 會直接在PLC Soft内進行軸№表示以防止失誤。 | N41: 初回 | O41: 0 | P41: 0 | R41: 情報 | S41: 情報 | T41: 情報 | U41: 情報 | V41: 情報 | W41: 情報 | X41: 要 | Y41: Soft變更時製造的立會及不要忘記聯絡的事項，已向ADT設技再次依賴完畢。 | Z41: - | AA41: - | AB41: - | AC41: - | AD41: - | AE41: - | AF41: 完了 | AG41: =IF(Y41="","","CLOSE") -> CLOSE | AH41: =IF(E41="","",IF(COUNTIF(Z41:AE41,"未")=0,"CLOSE","")) -> CLOSE | AI41: =COUNTIF(Z41:AF41,"完了")/COUNTIF(R41:X41,"要") -> 1
...

Sheet 横展開フロー（TPM) 
A1: [ＴＰＭ] 他拠点との情報交換 | P1: 42558 | R1: rev2

Sheet Sheet1
B9: № | C9: 横展開内容 | D9: 横展開未ライン
B10: 15 | C10: ・チェーンの交換記録有無の確認 ・定期定修の頻度を担当者会議で機械Gと各窯討論 | D10: KF
B11: 20 | C11: ・シンクライアントHUBのケーブル抜け防止処置。 ・HUB周辺の清掃 | D11: KF | E11: 目前精查hub電回收，待稼動前實施
B12: 22 | C12: ・本線増速C/V№4のアイドラーシャフト材質変更（SCM435) | D12: KF | E12: 機械購入中！
B13: 28 | C13: ・縦切り機PLC故障の際も本線マスタPLCから警報出力されるようソフト改造 | D13: YF/ZF | E13: 設備依賴書已經提出！
B14: 30 | C14: ・カッター昇降CYL及びLMガイドの点検。 ・昇降動作に左右バラツキが発生した時は製造で調整せず機械へ連絡する事を徹底。 | D14: KF/TAS | E14: 週間會議時向機械提出依賴點檢
B15: 32 | C15: ・アイアンラバーベルト（時規皮帶）の点検（SAMP） | D15: KF | E15: 週間會議時向機械提出依賴點檢
B16: 34 | C16: ・定寸送り用サーボMで過負荷異常が発生する際は、ベルトの偏りによる可能性がある事を オペレーターへ教育実施。 | D16: KF | E16: 10/2異常發生案例實施教育（股長教育說明OK）
B17: 38 | C17: ・BURベースの固定ボルトの緩み確認 | D17: CF/KF | E17: 10/2進行點檢（點檢OK）
B18: 16 | C18: ・採板Robot UPS電源異常
B20: 11/4會議中AI
B21: 1.ADT橫展開SHEET有部份內容希望日文化

Sheet 工作表1

Sheet Sheet2
D10: 窯別 | E10: 橫展開（未實施）項目
D11: YF | E11: 第7、8、46、52、53
D12: ZF | E12: 第7、8、29、37、46、53
D13: CF | E13: 第7、16、29、46、50、53
D14: EF | E14: 第7、13、16、29、46、53
D15: JF | E15: 第7、8、16、46、50、53
D16: KF | E16: 第4、16、28、29、46、53
D17: TAS | E17: 第16、30、36、47
D18: OFF | E18: 第36、47

Sheet 横展開フロー（ADT)
A1: [ADT] 他窯との情報交換 | P1: 41827 | R1: rev1

Sheet 2018~設技･製造担当者_OLD
A1: 設備横展開担当者（担当者会議） | I1: 43115
G3: 横展開必要時聯絡先(必須）
A6: （敬称略）
G7: 日籍
B8: アドバイス | C8: 機械 林文勇 | G8: アドバイス | H8: 機械 ： 久野 | I8: 服部
B9: アドバイス | C9: 電気 黃深儀 | H9: 電気 ： 伊藤 | I9: 木村
A11: 台籍 | B11: リーダー | H11: 機械 | I11: 電気
B12: 機：黃奮志 | G12: 日籍 | H12: 後藤 | I12: 池田
B13: 電：許景晨
A14: 窯別 | B14: 主担当 | C14: 副担当
A15: YZ | B15: 機：林聖景 | C15: 機：廖得亨
B16: 電：黃瓘峻 | C16: 電：林逸樺
A17: CE （TAS含） | B17: 機：莊森為 | C17: 機：曾孟文
B18: 電：廖士智 | C18: 電：張水亮
A19: JK （TAS含） | B19: 機：高銘壕 | C19: 機：蔡志明
B20: 電：許俊彬 | C20: 電：邱文仁
G24: 日籍
B25: アドバイス | C25: 吳 清池 | G25: アドバイス | H25: 古閑 | I25: 三宅
B26: アドバイス | C26: 鄭 吉勝 | H26: 八尾 | I26: 藤原
H27: 主担当 | I27: 副担当
A28: 台籍 | B28: ﾘｰﾀﾞｰ | C28: ｻﾌﾞ | G28: 日籍 | H28: 切原 | I28: 中谷 | J28: 深町
B29: 陳 勝立 | C29: 邱 世文
A30: 窯別 | B30: LINE擔當 | C30: 主担当 | D30: 副担当
A31: YF | B31: 劉芳全 | C31: 許仕明 | D31: 林診輝
A32: CF | B32: 吳得祿 | C32: 吳學典 | D32: 曾隆盛
A33: EF | B33: 李炳興 | C33: 王文佑 | D33: 許建生
A34: JF | B34: 謝坤瀚 | C34: 朱峰謀 | D34: 吳洺偉
A35: KF | B35: 黃乙原 | C35: 張崇慶 | D35: 賴勃伸
A36: TAS | B36: 楊焜旭(劉佳明) | C36: 陳振遠 | D36: 邱信翔

Sheet 進捗確認シート (2)
A1: ADT 設備異常・設備改善 横展開進捗確認Sheet | H1: =SUM(H17:H152) -> 0 | S1: ★ADT各ライン | T1: 横展開対応状況
A2: ★ADT全ライン | T2: YF | X2: ZF | AB2: CF | AF2: EF | AJ2: JF | AN2: KF | AR2: TAS | AV2: OFF切
B3: 件数 | D3: 方針完了 | S3: 横展開必要件数 全拠点 | T3: =COUNTIF(T153:T453,"要") -> 9 | X3: =COUNTIF(X153:X453,"要") -> 0 | AB3: =COUNTIF(AB153:AB453,"要") -> 12 | AF3: =COUNTIF(AF153:AF453,"要") -> 11 | AJ3: =COUNTIF(AJ153:AJ453,"要") -> 12 | AN3: =COUNTIF(AN153:AN453,"要") -> 12 | AR3: =COUNTIF(AR153:AR453,"要") -> 4 | AV3: =COUNTIF(AV153:AV453,"要") -> 3
A4: 他拠点 | B4: =COUNTIF($J$153:$J$453,1) -> 4 | D4: =COUNTIF(L153:L453,2) -> 4 | E4: =D4/B4 -> 1 | S4: 横展開完了件数 全拠点 | T4: =COUNTIF(BB153:BB453,"完了") -> 8 | X4: =COUNTIF(BF153:BF453,"完了") -> 0 | AB4: =COUNTIF(BJ153:BJ453,"完了") -> 11 | AF4: =COUNTIF(BN153:BN453,"完了") -> 11 | AJ4: =COUNTIF(BR153:BR453,"完了") -> 13 | AN4: =COUNTIF(BV153:BV453,"完了") -> 13 | AR4: =COUNTIF(BZ153:BZ453,"完了") -> 4 | AV4: =COUNTIF(CD153:CD453,"完了") -> 3
A5: ADT内 | B5: =COUNTIF($J$153:$J$453,2) -> 11 | D5: =COUNTIF(L153:L453,3) -> 11 | E5: =D5/B5 -> 1 | S5: 横展開完了率 全拠点 | T5: =T4/T3 -> 0.88888889 | X5: =X4/X3 -> #DIV/0! | AB5: =AB4/AB3 -> 0.91666667 | AF5: =AF4/AF3 -> 1 | AJ5: =AJ4/AJ3 -> 1.0833333 | AN5: =AN4/AN3 -> 1.0833333 | AR5: =AR4/AR3 -> 1 | AV5: =AV4/AV3 -> 1 | CL5: 異常報告書（中文）共有フォルダ
A6: 全拠点 | B6: =COUNTIF(H$153:H$453,"1") -> 15 | D6: =D4+D5 -> 15 | E6: =D6/B6 -> 1 | T6: =SUM(T4:AY4)/SUM(T3:AY3) -> 1
B8: 件数 | D8: 対応完了 | S8: 横展開必要件数 ADT内 | T8: =COUNTIF(W153:W453,2) -> 6 | X8: =COUNTIF(AA153:AA453,2) -> 0 | AB8: =COUNTIF(AE153:AE453,2) -> 9 | AF8: =COUNTIF(AI153:AI453,2) -> 8 | AJ8: =COUNTIF(AM153:AM453,2) -> 8 | AN8: =COUNTIF(AQ153:AQ453,2) -> 8 | AR8: =COUNTIF(AU153:AU453,2) -> 3 | AV8: =COUNTIF(AY153:AY453,2) -> 2 | CL8: 異常報告書（日文）共有フォルダ
A9: 他拠点 | B9: =COUNTIF($J$153:$J$453,1) -> 4 | D9: =COUNTIF(N153:N453,2) -> 4 | E9: =D9/B9 -> 1 | S9: 横展開完了件数 ADT内 | T9: =COUNTIF(BE153:BE453,2) -> 5 | X9: =COUNTIF(BI153:BI453,2) -> 0 | AB9: =COUNTIF(BM153:BM453,2) -> 8 | AF9: =COUNTIF(BQ153:BQ453,2) -> 8 | AJ9: =COUNTIF(BU153:BU453,2) -> 9 | AN9: =COUNTIF(BY153:BY453,2) -> 9 | AR9: =COUNTIF(CC153:CC453,2) -> 3 | AV9: =COUNTIF(CG153:CG453,2) -> 2
A10: ADT内 | B10: =COUNTIF($J$153:$J$453,2) -> 11 | D10: =COUNTIF(N153:N453,3) -> 10 | E10: =D10/B10 -> 0.90909091 | S10: 横展開完了率 ADT内 | T10: =T9/T8 -> 0.83333333 | X10: =X9/X8 -> #DIV/0! | AB10: =AB9/AB8 -> 0.88888889 | AF10: =AF9/AF8 -> 1 | AJ10: =AJ9/AJ8 -> 1.125 | AN10: =AN9/AN8 -> 1.125 | AR10: =AR9/AR8 -> 1 | AV10: =AV9/AV8 -> 1
A11: 全拠点 | B11: =COUNTIF(H$153:H$453,"1") -> 15 | D11: =D9+D10 -> 14 | E11: =D11/B11 -> 0.93333333 | T11: =SUM(T9:AY9)/SUM(T8:AY8) -> 1
CQ12: 橫展開完成率=
CN13: =COUNTIF(CN153:CN252,"CLOSE") -> 20 | CQ13: =CN13/C15 -> 0.95238095
C15: =COUNTA(C153:C252) -> 21 | T15: 横展開必要ライン | BB15: 横展開対応進捗 | CH15: 資料保存先 | CM15: 方針 | CN15: 対応 | CQ15: 対応進捗状況の詳細コメント
A16: № | B16: 日付 | C16: 月份 | D16: 場所（1） | E16: 場所（2） | F16: 担当者 | G16: 要フラグ | H16: 要フラグ2 | I16: ADT+要 | J16: ADTor他拠点 | K16: 方針完了 フラグ | L16: 方針完了 フラグ2 | M16: 対応完了 フラグ | N16: 対応完了 フラグ2 | O16: 種別 | P16: 設備名 | Q16: 内容 | R16: 原因調査結果 | S16: 対策内容 | T16: YF | U16: YF | V16: YF | W16: YF | X16: ZF | Y16: ZF | Z16: ZF | AA16: ZF | AB16: CF | AC16: CF | AD16: CF | AE16: CF | AF16: EF | AG16: EF | AH16: EF | AI16: EF | AJ16: JF | AK16: JF | AL16: JF | AM16: JF | AN16: KF | AO16: KF | AP16: KF | AQ16: KF | AR16: TAS | AS16: TAS | AT16: TAS | AU16: TAS | AV16: OFF切 | AW16: OFF切 | AX16: OFF切 | AY16: OFF切 | AZ16: 横展開対応内容 | BA16: 目標期限 | BB16: YF | BC16: YF | BD16: YF | BE16: YF | BF16: ZF | BG16: ZF | BH16: ZF | BI16: ZF | BJ16: CF | BK16: CF | BL16: CF | BM16: CF | BN16: EF | BO16: EF | BP16: EF | BQ16: EF | BR16: JF | BS16: JF | BT16: JF | BU16: JF | BV16: KF | BW16: KF | BX16: KF | BY16: KF | BZ16: TAS | CA16: TAS | CB16: TAS | CC16: TAS | CD16: OFF切 | CE16: OFF切 | CF16: OFF切 | CG16: OFF切 | CH16: 日文 | CI16: 初回/ 再發 | CJ16: 中文 | CK16: LOSS m2 | CL16: 関係資料 | CM16: CLOSE | CN16: CLOSE | CO16: 停止 時間 (MIN) | CP16: 機會 損失 (m2) | CQ16: YF | CR16: ZF | CS16: CF | CT16: EF | CU16: JF | CV16: KF | CW16: TAS | CX16: OFF | CY16: コメント
A17: 1 | B17: 41798 | C17: =MONTH(B17) -> 6 | D17: ADT | E17: JF | F17: 三路 | G17: =COUNTIF(T17:AV17,"要") -> 5 | H17: =IF(G17>0,"1","0") -> 1 | I17: =IF(AND(D17="ADT",H17="1"),"1","0") -> 1 | J17: =H17+I17 -> 2 | K17: =IF(CM17="CLOSE",1,"") -> 1 | L17: =J17+K17 -> 3 | M17: =IF(CN17="CLOSE",1,"") -> 1 | N17: =J17+M17 -> 3 | O17: 検査機系異常 | P17: TOM3 | Q17: ・歪CAMERA#4 故障 | R17: ・第4TAP發生鬍鬚状的雜訊。 ※推測是歪CAMERA内部的接点不良。 | S17: ・CAMERA更換 ・在歪CAMERA的異常発現用處作成#970GATE ・作成和教育光量異常警報発生時，異常画像発現時的作業流程。 | T17: 要 | U17: =IF($D17="ADT","1","") -> 1 | V17: =IF(T17="要","1","") -> 1 | W17: =U17+V17 -> 2 | X17: 要 | Y17: =IF($D17="ADT","1","") -> 1 | Z17: =IF(X17="要","1","") -> 1 | AA17: =Y17+Z17 -> 2 | AB17: 要 | AC17: =IF($D17="ADT","1","") -> 1 | AD17: =IF(AB17="要","1","") -> 1 | AE17: =AC17+AD17 -> 2 | AF17: 要 | AG17: =IF($D17="ADT","1","") -> 1 | AH17: =IF(AF17="要","1","") -> 1 | AI17: =AG17+AH17 -> 2 | AJ17: － | AK17: =IF($D17="ADT","1","") -> 1 | AL17: =IF(AJ17="要","1","") | AM17: =AK17+AL17 -> #VALUE! | AN17: 要 | AO17: =IF($D17="ADT","1","") -> 1 | AP17: =IF(AN17="要","1","") -> 1 | AQ17: =AO17+AP17 -> 2 | AR17: － | AS17: =IF($D17="ADT","1","") -> 1 | AT17: =IF(AR17="要","1","") | AU17: =AS17+AT17 -> #VALUE! | AV17: － | AW17: =IF($D17="ADT","1","") -> 1 | AX17: =IF(AV17="要","1","") | AY17: =AW17+AX17 -> #VALUE! | AZ17: ・追加#970GATE ・教育光量異常警報発生時，異常画像発現時的作業流程。 | BA17: 41851 | BB17: 完了 | BC17: =IF($D17="ADT","1","") -> 1 | BD17: =IF(BB17="完了","1","") -> 1 | BE17: =BC17+BD17 -> 2 | BF17: 完了 | BG17: =IF($D17="ADT","1","") -> 1 | BH17: =IF(BF17="完了","1","") -> 1 | BI17: =BG17+BH17 -> 2 | BJ17: 完了 | BK17: =IF($D17="ADT","1","") -> 1 | BL17: =IF(BJ17="完了","1","") -> 1 | BM17: =BK17+BL17 -> 2 | BN17: 完了 | BO17: =IF($D17="ADT","1","") -> 1 | BP17: =IF(BN17="完了","1","") -> 1 | BQ17: =BO17+BP17 -> 2 | BR17: － | BS17: =IF($D17="ADT","1","") -> 1 | BT17: =IF(BR17="完了","1","") | BU17: =BS17+BT17 -> #VALUE! | BV17: 完了 | BW17: =IF($D17="ADT","1","") -> 1 | BX17: =IF(BV17="完了","1","") -> 1 | BY17: =BW17+BX17 -> 2 | BZ17: － | CA17: =IF($D17="ADT","1","") -> 1 | CB17: =IF(BZ17="完了","1","") | CC17: =CA17+CB17 -> #VALUE! | CD17: － | CE17: =IF($D17="ADT","1","") -> 1 | CF17: =IF(CD17="完了","1","") | CG17: =CE17+CF17 -> #VALUE! | CH17: O:\00 製造一部共通\横展開確認\設備異常報告\異常報告書(日文)\201406 | CI17: 0 | CK17: 259 | CM17: =IF(AZ17="","","CLOSE") -> CLOSE | CN17: =IF(F17="","",IF(COUNTIF(BB17:CE17,"未")=0,"CLOSE","")) -> CLOSE | CO17: 10 | CQ17: CLOSE | CR17: CLOSE | CS17: CLOSE | CT17: CLOSE | CU17: CLOSE | CV17: CLOSE | CW17: CLOSE | CX17: CLOSE
A18: 2 | B18: 41812 | C18: =MONTH(B18) -> 6 | D18: ADT | E18: JF | F18: 蔡明建 三路 | G18: =COUNTIF(T18:AV18,"要") -> 5 | H18: =IF(G18>0,"1","0") -> 1 | I18: =IF(AND(D18="ADT",H18="1"),"1","0") -> 1 | J18: =H18+I18 -> 2 | K18: =IF(CM18="CLOSE",1,"") -> 1 | L18: =J18+K18 -> 3 | M18: =IF(CN18="CLOSE",1,"") -> 1 | N18: =J18+M18 -> 3 | O18: 検査機系異常 | P18: WI | Q18: ・WI CAMERA#11波形異常 | R18: ・推測有落下物掉在CAMERA或光原條紋片上。 ※造成波形異常,影響了平坦度值。 | S18: ・拖出WI光源CAMERA基座,用AIR清除灰塵異物 ・制定連續平坦度惡化時確認流程並教育訓練 ・制定WI光源CAMERA基座拖出的手順並教育訓練. | T18: 要 | U18: =IF($D18="ADT","1","") -> 1 | V18: =IF(T18="要","1","") -> 1 | W18: =U18+V18 -> 2 | X18: 要 | Y18: =IF($D18="ADT","1","") -> 1 | Z18: =IF(X18="要","1","") -> 1 | AA18: =Y18+Z18 -> 2 | AB18: 要 | AC18: =IF($D18="ADT","1","") -> 1 | AD18: =IF(AB18="要","1","") -> 1 | AE18: =AC18+AD18 -> 2 | AF18: 要 | AG18: =IF($D18="ADT","1","") -> 1 | AH18: =IF(AF18="要","1","") -> 1 | AI18: =AG18+AH18 -> 2 | AJ18: － | AK18: =IF($D18="ADT","1","") -> 1 | AL18: =IF(AJ18="要","1","") | AM18: =AK18+AL18 -> #VALUE! | AN18: 要 | AO18: =IF($D18="ADT","1","") -> 1 | AP18: =IF(AN18="要","1","") -> 1 | AQ18: =AO18+AP18 -> 2 | AR18: － | AS18: =IF($D18="ADT","1","") -> 1 | AT18: =IF(AR18="要","1","") | AU18: =AS18+AT18 -> #VALUE! | AV18: － | AW18: =IF($D18="ADT","1","") -> 1 | AX18: =IF(AV18="要","1","") | AY18: =AW18+AX18 -> #VALUE! | AZ18: ・制定連續平坦度惡化時確認流程並教育訓練。 ・制定WI光源CAMERA基座拖出的手順並教育訓練. | BA18: 41838 | BB18: 完了 | BC18: =IF($D18="ADT","1","") -> 1 | BD18: =IF(BB18="完了","1","") -> 1 | BE18: =BC18+BD18 -> 2 | BF18: 完了 | BG18: =IF($D18="ADT","1","") -> 1 | BH18: =IF(BF18="完了","1","") -> 1 | BI18: =BG18+BH18 -> 2 | BJ18: 完了 | BK18: =IF($D18="ADT","1","") -> 1 | BL18: =IF(BJ18="完了","1","") -> 1 | BM18: =BK18+BL18 -> 2 | BN18: 完了 | BO18: =IF($D18="ADT","1","") -> 1 | BP18: =IF(BN18="完了","1","") -> 1 | BQ18: =BO18+BP18 -> 2 | BR18: － | BS18: =IF($D18="ADT","1","") -> 1 | BT18: =IF(BR18="完了","1","") | BU18: =BS18+BT18 -> #VALUE! | BV18: 完了 | BW18: =IF($D18="ADT","1","") -> 1 | BX18: =IF(BV18="完了","1","") -> 1 | BY18: =BW18+BX18 -> 2 | BZ18: － | CA18: =IF($D18="ADT","1","") -> 1 | CB18: =IF(BZ18="完了","1","") | CC18: =CA18+CB18 -> #VALUE! | CD18: － | CE18: =IF($D18="ADT","1","") -> 1 | CF18: =IF(CD18="完了","1","") | CG18: =CE18+CF18 -> #VALUE! | CH18: O:\00 製造一部共通\横展開確認\設備異常報告\異常報告書(日文) | CI18: 0 | CJ18: O:\00 製造一部共通\横展開確認\設備異常報告\異常報告書(日文) | CK18: 0 | CL18: O:\00 製造一部共通\横展開確認\設備異常報告\異常報告書(日文)\201406\WI台車抜き出しマニュアル | CM18: =IF(AZ18="","","CLOSE") -> CLOSE | CN18: =IF(F18="","",IF(COUNTIF(BB18:CE18,"未")=0,"CLOSE","")) -> CLOSE | CO18: 0 | CQ18: CLOSE | CR18: CLOSE | CS18: CLOSE | CT18: CLOSE | CU18: CLOSE | CV18: CLOSE | CW18: CLOSE | CX18: CLOSE
A19: 3 | B19: 41798 | C19: =MONTH(B19) -> 6 | D19: AFK | E19: LF | F19: 鄭吉勝 | G19: =COUNTIF(T19:AV19,"要") -> 7 | H19: =IF(G19>0,"1","0") -> 1 | I19: =IF(AND(D19="ADT",H19="1"),"1","0") -> 0 | J19: =H19+I19 -> 1 | K19: =IF(CM19="CLOSE",1,"") -> 1 | L19: =J19+K19 -> 2 | M19: =IF(CN19="CLOSE",1,"") -> 1 | N19: =J19+M19 -> 2 | O19: 電気系異常 | P19: 帯電Bar | Q19: ・LF 帯電装置過電流Trip異常 | R19: ・現場濕度高（65%）的状態下、電荷從帶電Bar樹脂部之裂縫、或是樹脂部的髒污處流竄到支架上，導致過電流並跳脫。 ・由於使用高電壓、絶縁部多少都會因為電氣流動的因素產生裂縫。 | S19: ・工事日時都針對帶電Bar樹脂部實施掃除。 ・裂縫實施Silicon Caulking。 ・帶電Bar的下方設置傳導體（SUS pipe） | T19: 要 | U19: =IF($D19="ADT","1","") | V19: =IF(T19="要","1","") -> 1 | W19: =U19+V19 -> #VALUE! | X19: 要 | Y19: =IF($D19="ADT","1","") | Z19: =IF(X19="要","1","") -> 1 | AA19: =Y19+Z19 -> #VALUE! | AB19: 要 | AC19: =IF($D19="ADT","1","") | AD19: =IF(AB19="要","1","") -> 1 | AE19: =AC19+AD19 -> #VALUE! | AF19: 要 | AG19: =IF($D19="ADT","1","") | AH19: =IF(AF19="要","1","") -> 1 | AI19: =AG19+AH19 -> #VALUE! | AJ19: 要 | AK19: =IF($D19="ADT","1","") | AL19: =IF(AJ19="要","1","") -> 1 | AM19: =AK19+AL19 -> #VALUE! | AN19: 要 | AO19: =IF($D19="ADT","1","") | AP19: =IF(AN19="要","1","") -> 1 | AQ19: =AO19+AP19 -> #VALUE! | AR19: 要 | AS19: =IF($D19="ADT","1","") | AT19: =IF(AR19="要","1","") -> 1 | AU19: =AS19+AT19 -> #VALUE! | AV19: － | AW19: =IF($D19="ADT","1","") | AX19: =IF(AV19="要","1","") | AY19: =AW19+AX19 -> #VALUE! | AZ19: ・帶電Bar數量確認 ・帶電Bar本體點檢 ・掃除/點檢頻度確認 | BA19: 41820 | BB19: 完了 | BC19: =IF($D19="ADT","1","") | BD19: =IF(BB19="完了","1","") -> 1 | BE19: =BC19+BD19 -> #VALUE! | BF19: 完了 | BG19: =IF($D19="ADT","1","") | BH19: =IF(BF19="完了","1","") -> 1 | BI19: =BG19+BH19 -> #VALUE! | BJ19: 完了 | BK19: =IF($D19="ADT","1","") | BL19: =IF(BJ19="完了","1","") -> 1 | BM19: =BK19+BL19 -> #VALUE! | BN19: 完了 | BO19: =IF($D19="ADT","1","") | BP19: =IF(BN19="完了","1","") -> 1 | BQ19: =BO19+BP19 -> #VALUE! | BR19: 完了 | BS19: =IF($D19="ADT","1","") | BT19: =IF(BR19="完了","1","") -> 1 | BU19: =BS19+BT19 -> #VALUE! | BV19: 完了 | BW19: =IF($D19="ADT","1","") | BX19: =IF(BV19="完了","1","") -> 1 | BY19: =BW19+BX19 -> #VALUE! | BZ19: 完了 | CA19: =IF($D19="ADT","1","") | CB19: =IF(BZ19="完了","1","") -> 1 | CC19: =CA19+CB19 -> #VALUE! | CD19: － | CE19: =IF($D19="ADT","1","") | CF19: =IF(CD19="完了","1","") | CG19: =CE19+CF19 -> #VALUE! | CH19: 異常報告書（日文）共有フォルダ\20140608 LF帯電装置過電流Trip異常_.xlsx | CI19: 0 | CK19: 2820 | CL19: ..\..\異常報告書(中文)\201406\●LF帯電装置過電流Trip異常-(C_E_J_K_Y_Z)帶電Bar確認.xls | CM19: =IF(AZ19="","","CLOSE") -> CLOSE | CN19: =IF(F19="","",IF(COUNTIF(BB19:CE19,"未")=0,"CLOSE","")) -> CLOSE | CO19: 95 | CQ19: CLOSE | CR19: CLOSE | CS19: CLOSE | CT19: CLOSE | CU19: CLOSE | CV19: CLOSE | CW19: CLOSE | CX19: CLOSE
A20: 4 | B20: 41820 | C20: =MONTH(B20) -> 6 | D20: 全拠点 | E20: 全ライン | F20: 三路 | G20: =COUNTIF(T20:AV20,"要") -> 6 | H20: =IF(G20>0,"1","0") -> 1 | I20: =IF(AND(D20="ADT",H20="1"),"1","0") -> 0 | J20: =H20+I20 -> 1 | K20: =IF(CM20="CLOSE",1,"") -> 1 | L20: =J20+K20 -> 2 | M20: =IF(CN20="CLOSE",1,"") -> 1 | N20: =J20+M20 -> 2 | O20: システム系異常 | P20: PAM | Q20: ・PL№無法連結 | R20: ・相同的生産指示書號碼進行2次以上J/C時，發生與PAM内部所持有的號碼不一致，造成PLNo無法連結的現象。 | S20: ・修正版的發行 | T20: 要 | U20: =IF($D20="ADT","1","") | V20: =IF(T20="要","1","") -> 1 | W20: =U20+V20 -> #VALUE! | X20: 要 | Y20: =IF($D20="ADT","1","") | Z20: =IF(X20="要","1","") -> 1 | AA20: =Y20+Z20 -> #VALUE! | AB20: 要 | AC20: =IF($D20="ADT","1","") | AD20: =IF(AB20="要","1","") -> 1 | AE20: =AC20+AD20 -> #VALUE! | AF20: 要 | AG20: =IF($D20="ADT","1","") | AH20: =IF(AF20="要","1","") -> 1 | AI20: =AG20+AH20 -> #VALUE! | AJ20: 要 | AK20: =IF($D20="ADT","1","") | AL20: =IF(AJ20="要","1","") -> 1 | AM20: =AK20+AL20 -> #VALUE! | AN20: 要 | AO20: =IF($D20="ADT","1","") | AP20: =IF(AN20="要","1","") -> 1 | AQ20: =AO20+AP20 -> #VALUE! | AR20: － | AS20: =IF($D20="ADT","1","") | AT20: =IF(AR20="要","1","") | AU20: =AS20+AT20 -> #VALUE! | AV20: － | AW20: =IF($D20="ADT","1","") | AX20: =IF(AV20="要","1","") | AY20: =AW20+AX20 -> #VALUE! | AZ20: ・修正版的發行 | BB20: 完了 | BC20: =IF($D20="ADT","1","") | BD20: =IF(BB20="完了","1","") -> 1 | BE20: =BC20+BD20 -> #VALUE! | BF20: 完了 | BG20: =IF($D20="ADT","1","") | BH20: =IF(BF20="完了","1","") -> 1 | BI20: =BG20+BH20 -> #VALUE! | BJ20: 完了 | BK20: =IF($D20="ADT","1","") | BL20: =IF(BJ20="完了","1","") -> 1 | BM20: =BK20+BL20 -> #VALUE! | BN20: 完了 | BO20: =IF($D20="ADT","1","") | BP20: =IF(BN20="完了","1","") -> 1 | BQ20: =BO20+BP20 -> #VALUE! | BR20: 完了 | BS20: =IF($D20="ADT","1","") | BT20: =IF(BR20="完了","1","") -> 1 | BU20: =BS20+BT20 -> #VALUE! | BV20: 完了 | BW20: =IF($D20="ADT","1","") | BX20: =IF(BV20="完了","1","") -> 1 | BY20: =BW20+BX20 -> #VALUE! | BZ20: － | CA20: =IF($D20="ADT","1","") | CB20: =IF(BZ20="完了","1","") | CC20: =CA20+CB20 -> #VALUE! | CD20: － | CE20: =IF($D20="ADT","1","") | CF20: =IF(CD20="完了","1","") | CG20: =CE20+CF20 -> #VALUE! | CH20: O:\00 製造一部共通\横展開確認\設備異常報告\異常報告書(日文)\201406\20140630 PAM改修.xls | CI20: 0 | CK20: 0 | CL20: O:\00 製造一部共通\横展開確認\設備異常報告\異常報告書(日文)\201406\20140630 PAM改修.xls | CM20: =IF(AZ20="","","CLOSE") -> CLOSE | CN20: =IF(F20="","",IF(COUNTIF(BB20:CE20,"未")=0,"CLOSE","")) -> CLOSE | CO20: 0 | CQ20: CLOSE | CR20: CLOSE | CS20: CLOSE | CT20: CLOSE | CU20: CLOSE | CV20: KF冷修導入預定！方針已決定一時COLSE | CW20: CLOSE | CX20: CLOSE
A21: 5 | B21: 41823 | C21: =MONTH(B21) -> 7 | D21: ADT | E21: CF | F21: 蔵光 | G21: =COUNTIF(T21:AV21,"要") -> 6 | H21: =IF(G21>0,"1","0") -> 1 | I21: =IF(AND(D21="ADT",H21="1"),"1","0") -> 1 | J21: =H21+I21 -> 2 | K21: =IF(CM21="CLOSE",1,"") -> 1 | L21: =J21+K21 -> 3 | M21: =IF(CN21="CLOSE",1,"") -> 1 | N21: =J21+M21 -> 3 | O21: 機械系異常 | P21: 本線C/V | Q21: ・CHAIN断裂異常 (2014/05/22) | R21: ・漏掉冷修後、初期伸長等的点検・確認 | S21: ・CHAIN鬆弛部位的可視化 | T21: 要 | U21: =IF($D21="ADT","1","") -> 1 | V21: =IF(T21="要","1","") -> 1 | W21: =U21+V21 -> 2 | X21: 要 | Y21: =IF($D21="ADT","1","") -> 1 | Z21: =IF(X21="要","1","") -> 1 | AA21: =Y21+Z21 -> 2 | AB21: 要 | AC21: =IF($D21="ADT","1","") -> 1 | AD21: =IF(AB21="要","1","") -> 1 | AE21: =AC21+AD21 -> 2 | AF21: 要 | AG21: =IF($D21="ADT","1","") -> 1 | AH21: =IF(AF21="要","1","") -> 1 | AI21: =AG21+AH21 -> 2 | AJ21: 要 | AK21: =IF($D21="ADT","1","") -> 1 | AL21: =IF(AJ21="要","1","") -> 1 | AM21: =AK21+AL21 -> 2 | AN21: 要 | AO21: =IF($D21="ADT","1","") -> 1 | AP21: =IF(AN21="要","1","") -> 1 | AQ21: =AO21+AP21 -> 2 | AR21: － | AS21: =IF($D21="ADT","1","") -> 1 | AT21: =IF(AR21="要","1","") | AU21: =AS21+AT21 -> #VALUE! | AV21: － | AW21: =IF($D21="ADT","1","") -> 1 | AX21: =IF(AV21="要","1","") | AY21: =AW21+AX21 -> #VALUE! | AZ21: ・CHAIN鬆弛部位的可視化 ・LINE SHAFT駆動部的可視化 ※（2014/7/24追記） | BB21: 完了 | BC21: =IF($D21="ADT","1","") -> 1 | BD21: =IF(BB21="完了","1","") -> 1 | BE21: =BC21+BD21 -> 2 | BF21: 完了 | BG21: =IF($D21="ADT","1","") -> 1 | BH21: =IF(BF21="完了","1","") -> 1 | BI21: =BG21+BH21 -> 2 | BJ21: 完了 | BK21: =IF($D21="ADT","1","") -> 1 | BL21: =IF(BJ21="完了","1","") -> 1 | BM21: =BK21+BL21 -> 2 | BN21: 完了 | BO21: =IF($D21="ADT","1","") -> 1 | BP21: =IF(BN21="完了","1","") -> 1 | BQ21: =BO21+BP21 -> 2 | BR21: 完了 | BS21: =IF($D21="ADT","1","") -> 1 | BT21: =IF(BR21="完了","1","") -> 1 | BU21: =BS21+BT21 -> 2 | BV21: 完了 | BW21: =IF($D21="ADT","1","") -> 1 | BX21: =IF(BV21="完了","1","") -> 1 | BY21: =BW21+BX21 -> 2 | BZ21: － | CA21: =IF($D21="ADT","1","") -> 1 | CB21: =IF(BZ21="完了","1","") | CC21: =CA21+CB21 -> #VALUE! | CD21: － | CE21: =IF($D21="ADT","1","") -> 1 | CF21: =IF(CD21="完了","1","") | CG21: =CE21+CF21 -> #VALUE! | CH21: 異常報告書（日文）共有フォルダ\20140522CF 本線CV駆動チェーン断裂異常.xlsx | CI21: 0 | CK21: 5531 | CL21: \\172.18.154.188\adt_public\08_部門情報\8552_素板製造-設備技術\【設備技術修繕紀錄】\03機械\各窯情報資料\20140522 CF本線段ROLL停止--各窯橫展開2014.0606.xls | CM21: =IF(AZ21="","","CLOSE") -> CLOSE | CN21: =IF(F21="","",IF(COUNTIF(BB21:CE21,"未")=0,"CLOSE","")) -> CLOSE | CO21: 259 | CQ21: CLOSE | CR21: CLOSE | CS21: CLOSE | CT21: CLOSE | CU21: CLOSE | CV21: CLOSE | CW21: CLOSE | CX21: CLOSE
A22: 6 | B22: 41823 | C22: =MONTH(B22) -> 7 | D22: ADT | E22: CF | F22: 蔵光 | G22: =COUNTIF(T22:AV22,"要") -> 6 | H22: =IF(G22>0,"1","0") -> 1 | I22: =IF(AND(D22="ADT",H22="1"),"1","0") -> 1 | J22: =H22+I22 -> 2 | K22: =IF(CM22="CLOSE",1,"") -> 1 | L22: =J22+K22 -> 3 | M22: =IF(CN22="CLOSE",1,"") -> 1 | N22: =J22+M22 -> 3 | O22: 機械系異常 | P22: 本線C/V | Q22: ・CHAIN断裂異常 (2014/05/22) | R22: ・漏掉冷修後、初期伸長等的点検・確認 | S22: ・CHAIN GUIDE的改造 | T22: 要 | U22: =IF($D22="ADT","1","") -> 1 | V22: =IF(T22="要","1","") -> 1 | W22: =U22+V22 -> 2 | X22: 要 | Y22: =IF($D22="ADT","1","") -> 1 | Z22: =IF(X22="要","1","") -> 1 | AA22: =Y22+Z22 -> 2 | AB22: 要 | AC22: =IF($D22="ADT","1","") -> 1 | AD22: =IF(AB22="要","1","") -> 1 | AE22: =AC22+AD22 -> 2 | AF22: 要 | AG22: =IF($D22="ADT","1","") -> 1 | AH22: =IF(AF22="要","1","") -> 1 | AI22: =AG22+AH22 -> 2 | AJ22: 要 | AK22: =IF($D22="ADT","1","") -> 1 | AL22: =IF(AJ22="要","1","") -> 1 | AM22: =AK22+AL22 -> 2 | AN22: 要 | AO22: =IF($D22="ADT","1","") -> 1 | AP22: =IF(AN22="要","1","") -> 1 | AQ22: =AO22+AP22 -> 2 | AR22: － | AS22: =IF($D22="ADT","1","") -> 1 | AT22: =IF(AR22="要","1","") | AU22: =AS22+AT22 -> #VALUE! | AV22: － | AW22: =IF($D22="ADT","1","") -> 1 | AX22: =IF(AV22="要","1","") | AY22: =AW22+AX22 -> #VALUE! | AZ22: ・CHAIN GUIDE的改造 | BB22: 完了 | BC22: =IF($D22="ADT","1","") -> 1 | BD22: =IF(BB22="完了","1","") -> 1 | BE22: =BC22+BD22 -> 2 | BF22: 完了 | BG22: =IF($D22="ADT","1","") -> 1 | BH22: =IF(BF22="完了","1","") -> 1 | BI22: =BG22+BH22 -> 2 | BJ22: 完了 | BK22: =IF($D22="ADT","1","") -> 1 | BL22: =IF(BJ22="完了","1","") -> 1 | BM22: =BK22+BL22 -> 2 | BN22: 完了 | BO22: =IF($D22="ADT","1","") -> 1 | BP22: =IF(BN22="完了","1","") -> 1 | BQ22: =BO22+BP22 -> 2 | BR22: 完了 | BS22: =IF($D22="ADT","1","") -> 1 | BT22: =IF(BR22="完了","1","") -> 1 | BU22: =BS22+BT22 -> 2 | BV22: 完了 | BW22: =IF($D22="ADT","1","") -> 1 | BX22: =IF(BV22="完了","1","") -> 1 | BY22: =BW22+BX22 -> 2 | BZ22: － | CA22: =IF($D22="ADT","1","") -> 1 | CB22: =IF(BZ22="完了","1","") | CC22: =CA22+CB22 -> #VALUE! | CD22: － | CE22: =IF($D22="ADT","1","") -> 1 | CF22: =IF(CD22="完了","1","") | CG22: =CE22+CF22 -> #VALUE! | CH22: \\172.18.154.189\mfg_public\00 製造一部共通\横展開確認\設備異常報告\異常報告書(日文)\201405\20140522CF 本線CV駆動チェーン断裂異常.xls | CL22: \\172.18.154.188\adt_public\08_部門情報\8552_素板製造-設備技術\【設備技術修繕紀錄】\03機械\各窯情報資料\20140522 CF本線段ROLL停止--各窯橫展開2014.0606.xls | CM22: =IF(AZ22="","","CLOSE") -> CLOSE | CN22: =IF(F22="","",IF(COUNTIF(BB22:CE22,"未")=0,"CLOSE","")) -> CLOSE | CQ22: CLOSE | CR22: CLOSE | CS22: CLOSE | CT22: CLOSE | CU22: CLOSE | CV22: CLOSE | CW22: CLOSE | CX22: CLOSE
A23: 7 | B23: 41823 | C23: =MONTH(B23) -> 7 | D23: ADT | E23: EF | F23: 万代 | G23: =COUNTIF(T23:AV23,"要") -> 6 | H23: =IF(G23>0,"1","0") -> 1 | I23: =IF(AND(D23="ADT",H23="1"),"1","0") -> 1 | J23: =H23+I23 -> 2 | K23: =IF(CM23="CLOSE",1,"") -> 1 | L23: =J23+K23 -> 3 | M23: =IF(CN23="CLOSE",1,"") -> 1 | N23: =J23+M23 -> 3 | O23: 機械系異常 | P23: 本線C/V | Q23: ・増速SHAFT折損 | R23: ・強度不足 | S23: ・本線増速立起部的CV-Roll SHAFT材質由SS400 25φ變更為SCM435 40φ | T23: 要 | U23: =IF($D23="ADT","1","") -> 1 | V23: =IF(T23="要","1","") -> 1 | W23: =U23+V23 -> 2 | X23: 要 | Y23: =IF($D23="ADT","1","") -> 1 | Z23: =IF(X23="要","1","") -> 1 | AA23: =Y23+Z23 -> 2 | AB23: 要 | AC23: =IF($D23="ADT","1","") -> 1 | AD23: =IF(AB23="要","1","") -> 1 | AE23: =AC23+AD23 -> 2 | AF23: 要 | AG23: =IF($D23="ADT","1","") -> 1 | AH23: =IF(AF23="要","1","") -> 1 | AI23: =AG23+AH23 -> 2 | AJ23: 要 | AK23: =IF($D23="ADT","1","") -> 1 | AL23: =IF(AJ23="要","1","") -> 1 | AM23: =AK23+AL23 -> 2 | AN23: 要 | AO23: =IF($D23="ADT","1","") -> 1 | AP23: =IF(AN23="要","1","") -> 1 | AQ23: =AO23+AP23 -> 2 | AR23: － | AS23: =IF($D23="ADT","1","") -> 1 | AT23: =IF(AR23="要","1","") | AU23: =AS23+AT23 -> #VALUE! | AV23: － | AW23: =IF($D23="ADT","1","") -> 1 | AX23: =IF(AV23="要","1","") | AY23: =AW23+AX23 -> #VALUE! | AZ23: ・更換SHAFT材質変更的roll | BB23: 完了 | BC23: =IF($D23="ADT","1","") -> 1 | BD23: =IF(BB23="完了","1","") -> 1 | BE23: =BC23+BD23 -> 2 | BF23: 完了 | BG23: =IF($D23="ADT","1","") -> 1 | BH23: =IF(BF23="完了","1","") -> 1 | BI23: =BG23+BH23 -> 2 | BJ23: 完了 | BK23: =IF($D23="ADT","1","") -> 1 | BL23: =IF(BJ23="完了","1","") -> 1 | BM23: =BK23+BL23 -> 2 | BN23: 完了 | BO23: =IF($D23="ADT","1","") -> 1 | BP23: =IF(BN23="完了","1","") -> 1 | BQ23: =BO23+BP23 -> 2 | BR23: 完了 | BS23: =IF($D23="ADT","1","") -> 1 | BT23: =IF(BR23="完了","1","") -> 1 | BU23: =BS23+BT23 -> 2 | BV23: 完了 | BW23: =IF($D23="ADT","1","") -> 1 | BX23: =IF(BV23="完了","1","") -> 1 | BY23: =BW23+BX23 -> 2 | BZ23: － | CA23: =IF($D23="ADT","1","") -> 1 | CB23: =IF(BZ23="完了","1","") | CC23: =CA23+CB23 -> #VALUE! | CD23: － | CE23: =IF($D23="ADT","1","") -> 1 | CF23: =IF(CD23="完了","1","") | CG23: =CE23+CF23 -> #VALUE! | CH23: \\172.18.154.189\mfg_public\00 製造一部共通\横展開確認\設備異常報告\異常報告書(日文)\201406\20140612EF EF本線増速CV＃4駆動ロールシャフト折損.xls | CI23: 1 | CK23: 0 | CM23: =IF(AZ23="","","CLOSE") -> CLOSE | CN23: =IF(F23="","",IF(COUNTIF(BB23:CE23,"未")=0,"CLOSE","")) -> CLOSE | CO23: 120 | CQ23: 機械回應：備品已到貨預定於1月份之工事日進行。 (因為YZ ROLL較短預計冷修時更換) | CR23: 機械回應：備品已到貨；因ZF工事日以0.2T相關改造優先，預定於4月份0.2T採板結束後之工事日進行。 (因為YZ ROLL較短預計冷修時更換) | CS23: CLOSE | CT23: 預計12/08擔當者會議提出討論，待會議後進行進度更新 | CU23: CLOSE | CV23: CLOSE | CW23: CLOSE | CX23: CLOSE | CY23: 方針CLOSE（冷修対応、来年費用など）
A24: 8 | B24: 41827 | C24: =MONTH(B24) -> 7 | D24: ADT | E24: EF | F24: 鄭吉勝 | G24: =COUNTIF(T24:AV24,"要") -> 6 | H24: =IF(G24>0,"1","0") -> 1 | I24: =IF(AND(D24="ADT",H24="1"),"1","0") -> 1 | J24: =H24+I24 -> 2 | K24: =IF(CM24="CLOSE",1,"") -> 1 | L24: =J24+K24 -> 3 | M24: =IF(CN24="CLOSE",1,"") -> 1 | N24: =J24+M24 -> 3 | O24: 機械系異常 | P24: BrC/V | Q24: 2Br増速C/V SHAFT破損異常 | R24: ・強度不足 | S24: ・由於現在R5加工的東西變為主流所以實施横展開。(入荷状況要確認） | T24: 要 | U24: =IF($D24="ADT","1","") -> 1 | V24: =IF(T24="要","1","") -> 1 | W24: =U24+V24 -> 2 | X24: 要 | Y24: =IF($D24="ADT","1","") -> 1 | Z24: =IF(X24="要","1","") -> 1 | AA24: =Y24+Z24 -> 2 | AB24: 要 | AC24: =IF($D24="ADT","1","") -> 1 | AD24: =IF(AB24="要","1","") -> 1 | AE24: =AC24+AD24 -> 2 | AF24: 要 | AG24: =IF($D24="ADT","1","") -> 1 | AH24: =IF(AF24="要","1","") -> 1 | AI24: =AG24+AH24 -> 2 | AJ24: 要 | AK24: =IF($D24="ADT","1","") -> 1 | AL24: =IF(AJ24="要","1","") -> 1 | AM24: =AK24+AL24 -> 2 | AN24: 要 | AO24: =IF($D24="ADT","1","") -> 1 | AP24: =IF(AN24="要","1","") -> 1 | AQ24: =AO24+AP24 -> 2 | AR24: － | AS24: =IF($D24="ADT","1","") -> 1 | AT24: =IF(AR24="要","1","") | AU24: =AS24+AT24 -> #VALUE! | AV24: － | AW24: =IF($D24="ADT","1","") -> 1 | AX24: =IF(AV24="要","1","") | AY24: =AW24+AX24 -> #VALUE! | AZ24: ・更換為SHAFT材質変更的roll (個別駆動後連結駆動的第一支（増速No.5）→SCM435（shaft径維持現狀） 利用全窯工事日時進行更新) | BB24: 完了 | BC24: =IF($D24="ADT","1","") -> 1 | BD24: =IF(BB24="完了","1","") -> 1 | BE24: =BC24+BD24 -> 2 | BF24: 完了 | BG24: =IF($D24="ADT","1","") -> 1 | BH24: =IF(BF24="完了","1","") -> 1 | BI24: =BG24+BH24 -> 2 | BJ24: 完了 | BK24: =IF($D24="ADT","1","") -> 1 | BL24: =IF(BJ24="完了","1","") -> 1 | BM24: =BK24+BL24 -> 2 | BN24: 完了 | BO24: =IF($D24="ADT","1","") -> 1 | BP24: =IF(BN24="完了","1","") -> 1 | BQ24: =BO24+BP24 -> 2 | BR24: 完了 | BS24: =IF($D24="ADT","1","") -> 1 | BT24: =IF(BR24="完了","1","") -> 1 | BU24: =BS24+BT24 -> 2 | BV24: 完了 | BW24: =IF($D24="ADT","1","") -> 1 | BX24: =IF(BV24="完了","1","") -> 1 | BY24: =BW24+BX24 -> 2 | BZ24: － | CA24: =IF($D24="ADT","1","") -> 1 | CB24: =IF(BZ24="完了","1","") | CC24: =CA24+CB24 -> #VALUE! | CD24: － | CE24: =IF($D24="ADT","1","") -> 1 | CF24: =IF(CD24="完了","1","") | CG24: =CE24+CF24 -> #VALUE! | CH24: 異常報告書（日文）共有フォルダ\其他\20130813EF (改定版）2Br増速CVシャフト破損トラフ゛ル.xlsx | CI24: 1 | CK24: 2.8 | CM24: =IF(AZ24="","","CLOSE") -> CLOSE | CN24: =IF(F24="","",IF(COUNTIF(BB24:CE24,"未")=0,"CLOSE","")) -> CLOSE | CQ24: 機械回應：備品已到貨預定於1月份之工事日進行。 (再確認更換時間) 冷修対応 10/1~所以先行結案完了 | CR24: 機械回應：備品已到貨；因ZF工事日以0.2T相關改造優先，預定於4月份0.2T採板結束後之工事日進行。 6/8已經更換完成 | CS24: CLOSE | CT24: CLOSE | CU24: CLOSE | CV24: CLOSE | CW24: CLOSE | CX24: CLOSE | CY24: 方針CLOSE（冷修対応、来年費用など）
A25: 9 | B25: 41809 | C25: =MONTH(B25) -> 6 | D25: AFK | E25: AFK OFF#2 | F25: 鄭吉勝 | G25: =COUNTIF(T25:AV25,"要") -> 8 | H25: =IF(G25>0,"1","0") -> 1 | I25: =IF(AND(D25="ADT",H25="1"),"1","0") -> 0 | J25: =H25+I25 -> 1 | K25: =IF(CM25="CLOSE",1,"") -> 1 | L25: =J25+K25 -> 2 | M25: =IF(CN25="CLOSE",1,"") -> 1 | N25: =J25+M25 -> 2 | O25: 電気系異常 | P25: OFF#2Line | Q25: X軸（電纜線燒毀）伺服機構異常 | R25: ・原因調查確認中！ | S25: ・電纜線的更換。 ・次回定修點檢確認 | T25: 要 | U25: =IF($D25="ADT","1","") | V25: =IF(T25="要","1","") -> 1 | W25: =U25+V25 -> #VALUE! | X25: 要 | Y25: =IF($D25="ADT","1","") | Z25: =IF(X25="要","1","") -> 1 | AA25: =Y25+Z25 -> #VALUE! | AB25: 要 | AC25: =IF($D25="ADT","1","") | AD25: =IF(AB25="要","1","") -> 1 | AE25: =AC25+AD25 -> #VALUE! | AF25: 要 | AG25: =IF($D25="ADT","1","") | AH25: =IF(AF25="要","1","") -> 1 | AI25: =AG25+AH25 -> #VALUE! | AJ25: 要 | AK25: =IF($D25="ADT","1","") | AL25: =IF(AJ25="要","1","") -> 1 | AM25: =AK25+AL25 -> #VALUE! | AN25: 要 | AO25: =IF($D25="ADT","1","") | AP25: =IF(AN25="要","1","") -> 1 | AQ25: =AO25+AP25 -> #VALUE! | AR25: 要 | AS25: =IF($D25="ADT","1","") | AT25: =IF(AR25="要","1","") -> 1 | AU25: =AS25+AT25 -> #VALUE! | AV25: 要 | AW25: =IF($D25="ADT","1","") | AX25: =IF(AV25="要","1","") -> 1 | AY25: =AW25+AX25 -> #VALUE! | AZ25: ・確認橫切機CABLEVEYOR 1.電纜線於CABLEVEYOR中排列是否整齊。 2.CABLEVEYOR中電纜線有無破損狀態。 3.CABLEVEYOR中電纜線有無皺摺或彎曲變形。 4.綑綁電纜線的線材（束帶）是否有斷掉。 | BA25: 41871 | BB25: 完了 | BC25: =IF($D25="ADT","1","") | BD25: =IF(BB25="完了","1","") -> 1 | BE25: =BC25+BD25 -> #VALUE! | BF25: 完了 | BG25: =IF($D25="ADT","1","") | BH25: =IF(BF25="完了","1","") -> 1 | BI25: =BG25+BH25 -> #VALUE! | BJ25: 完了 | BK25: =IF($D25="ADT","1","") | BL25: =IF(BJ25="完了","1","") -> 1 | BM25: =BK25+BL25 -> #VALUE! | BN25: 完了 | BO25: =IF($D25="ADT","1","") | BP25: =IF(BN25="完了","1","") -> 1 | BQ25: =BO25+BP25 -> #VALUE! | BR25: 完了 | BS25: =IF($D25="ADT","1","") | BT25: =IF(BR25="完了","1","") -> 1 | BU25: =BS25+BT25 -> #VALUE! | BV25: 完了 | BW25: =IF($D25="ADT","1","") | BX25: =IF(BV25="完了","1","") -> 1 | BY25: =BW25+BX25 -> #VALUE! | BZ25: 完了 | CA25: =IF($D25="ADT","1","") | CB25: =IF(BZ25="完了","1","") -> 1 | CC25: =CA25+CB25 -> #VALUE! | CD25: 完了 | CE25: =IF($D25="ADT","1","") | CF25: =IF(CD25="完了","1","") -> 1 | CG25: =CE25+CF25 -> #VALUE! | CH25: 異常報告書（日文）共有フォルダ\其他\20140619OFF切 OFF切2LineX軸（ケーブル焼損）サーボ異常.xlsx | CI25: 0 | CK25: 615 | CL25: 異常報告書（日文）共有フォルダ\其他\●AFK-OFF切#2LineX軸(電纜線焼毀)伺服機構異常-(C_E_J_K_Y_Z)CABLE Bear確認.xlsx | CM25: =IF(AZ25="","","CLOSE") -> CLOSE | CN25: =IF(F25="","",IF(COUNTIF(BB25:CE25,"未")=0,"CLOSE","")) -> CLOSE | CO25: 165 | CQ25: CLOSE | CR25: CLOSE | CS25: CLOSE | CT25: CLOSE | CU25: CLOSE | CV25: CLOSE | CW25: CLOSE | CX25: CLOSE
